Workbook
Name Career_Level: #REF!
Name Companies: OFFSET(#REF!,0,0,1,COUNTA(#REF!))
Name Companydata_ak: OFFSET(#REF!,-3,0,1,COUNTA(#REF!))
Name CompMap: OFFSET(#REF!,-2,0,1,COUNTA(#REF!))
Name CorporateCommunications: #REF!
Name cost.center_table: #REF!
Name cost.center_table.index: #REF!
Name dashboard.wf_table: #REF!
Name dashboard.wf_table.index: #REF!
Name DigitalandInformationSecurity: #REF!
Name DirectReport: #REF!
Name Division: #REF!
Name Driver: #REF!
Name Enforcement: #REF!
Name EvolutionWD: #REF!
Name FinanceandAdministration: #REF!
Name Frequency: الافتراضات!#REF!
Name GovernorOffice: #REF!
Name Grade.Mapping: #REF!
Name Grade.Mapping_Index: #REF!
Name HumanCapital: #REF!
Name ID_KPI_ForQuery: OFFSET(#REF!,0,0,COUNTA(#REF!),2)
Name InternalAudit: #REF!
Name International: #REF!
Name JFs: #REF!
Name l.cxo: #REF!
Name l.on.off: #REF!
Name LegalandCompliance: #REF!
Name newlegal: #REF!
Name nUsedCols: MATCH(REPT("z",255),#REF!)
Name nUsedRows: MATCH(REPT("z",255),#REF!)
Name Operations: #REF!
Name PositionDB: #REF!
Name PositionDB_Index: #REF!
Name PositionDB_Title: #REF!
Name POWER_USER_EXCEL_CHART_DD56D71F_F473_4FC5_B02E_EFE983EAFC0A: #REF!
Name Ratio: الافتراضات!#REF!
Name Regional: #REF!
Name RiskandIntelligence: #REF!
Name rngSal: #REF!
Name Sections_2020: OFFSET(#REF!,,,COUNTIF(#REF!,"<>"&"-"))
Name StrategyandTransformation: #REF!
Name TaxpayerExperienceandQuality: #REF!
Name Year: #REF!
Name تكرار: 'طريقة الحساب'!$B$2:$B$4
Name نسبة: 'طريقة الحساب'!$A$2

Sheet الافتراضات
A1: Assumptions
A4: General Assumptions | B4: Duration | C4: Unit | D4: Comments
A5: أيام العمل في الأسبوع | B5: 5 | C5: Days
A6: أيام العمل في السنة | B6: 48 | C6: Weeks
A7: ساعات العمل العادية في اليوم | B7: 7 | C7: Hours
A8: ساعات العمل العادية في الأسبوع | B8: =B7*B5 -> 35 | C8: Hours
A9: ساعات العمل العادية في السنة (من دون احتساب شهر رمضان) | B9: =(B8)*(B6) -> 1680 | C9: Hours
A10: ساعات العمل في شهر رمضان المبارك في اليوم | B10: 5 | C10: Hours
A11: أسابيع شهر رمضان المبارك | B11: 4 | C11: Weeks
A12: ساعات العمل في شهر رمضان المبارك (كامل الشهر) | B12: =B11*B10*B5 -> 100 | C12: Hours
A13: ساعات العمل العادية في السنة (مع احتساب شهر رمضان) | B13: =B9+B12 -> 1780 | C13: Hours
A14: ساعات العمل العادية في اليوم (مع احتساب شهر رمضان) | B14: =B13/((B6+B11)*5) -> 6.8461538 | C14: Hours
A15: إجازة عيد الفطر | B15: 5 | C15: Days
A16: إجازة عيد الأضحى | B16: 5 | C16: Days
A17: اليوم الوطني | B17: 1 | C17: Days
A18: يوم الرياضة الوطني | B18: 1 | C18: Days
A19: ساعات العمل بعد اقتطاع الإجازات | B19: =B13-(B15*B14)-(B16*B14)-(B17*B14)-(B18*B14) -> 1697.8462 | C19: Hours
A20: الإجازات السنوية | B20: 45 | C20: Days
A21: الإجازات السنوية (بالساعة) | B21: =B20*B14 -> 308.07692 | C21: Hours
A22: الإجازات المرضية | B22: 10 | C22: Days
A23: الإجازات المرضية (بالساعة) | B23: =B22*B14 -> 68.461538 | C23: Hours
A24: ساعات العمل بعد اقتطاع الإجازات السنوية والمرضية | B24: =B19-B21-B23 -> 1321.3077 | C24: Hours
A25: معدل الإنتاجية | B25: 0.75 | C25: %
A26: ساعات العمل المُعدِّلة في السنة | B26: =B25*B24 -> 990.98077 | C26: Hours
A27: دقائق العمل المُعدِّلة في السنة | B27: =B26*60 -> 59458.846 | C27: Minutes
A28: أيام العمل المُعدِّلة في السنة | B28: =((B6+B11)*B5)-B15-B16-B17-B18-B20-B22 -> 193 | C28: Days

Sheet طريقة الحساب
A1: نسبة | B1: تكرار
A2: عدد الموظفين/الوحدة | B2: دقائق
B3: ساعات
B4: أيام

Sheet نموذج التحليل
B1: مراجعة وتحديث محركات عبء العمل (المرحلة الثالثة من برنامج تخطيط القوى العاملة الحكومية)
B2: * للمزيد من الدعم، يرجى الرجوع إلى "إرشادات مراجعة وتحديث محركات عبء العمل" (PDF). في حال عدم استلامكم للوثيقة، يرجى طلبها من إدارة الموارد البشرية.
B4: المفتاح التوضيحي:
C5: خلايا مقفولة تحتوي على محركات عبء العمل للمرحلة الثانية من برنامج تخطيط القوى العاملة الحكومية
C6: خلايا مدخلات لمحركات عبء العمل الجديدة (حسب الحاجة)
C7: خلايا مدخلات لمراجعة البيانات وتحديثها (مثل متطلبات الحجم لفترة 2023 - 2029)
C8: خلايا مدخلات للبيانات الجديدة المطلوبة (مثل متطلبات الحجم لسنة 2030)
I9: المرحلة الثانية من برنامج تخطيط القوى العاملة الحكومية (2024 - للمرجعية) | S9: المرحلة الثالثة من برنامج تخطيط القوى العاملة الحكومية (2025 - للمراجعة) | AE9: مبرر تغييرات عبء العمل
S11: الحجم | AA11: الوقت/ النسبة | AE11: 0.15
B12: الجهة | C12: القطاع | D12: الإدارة | E12: القسم | F12: محرك عبء العمل | G12: طريقة الحساب | I12: 2023 | J12: 2024 | K12: 2025 | L12: 2026 | M12: 2027 | N12: 2028 | O12: 2029 | P12: المدة/النسبة | Q12: الوحدة | S12: 2023 | T12: 2024 | U12: 2025 | V12: 2026 | W12: 2027 | X12: 2028 | Y12: 2029 | Z12: 2030 | AA12: متطلبات الوقت/النسبة | AB12: الوحدة | AC12: الملاحظات | AE12: 2023 | AF12: 2024 | AG12: 2025 | AH12: 2026 | AI12: 2027 | AJ12: 2028 | AK12: 2029 | AL12: 2030 | AM12: Frequency/ Ratio | AN12: Unit | AO12: الحاجة إلى تبرير تغيير الحجم | AP12: مبرر تغيير الحجم | AQ12: الحاجة إلى تبرير متطلب الوقت/النسبة | AR12: مبرر تغيير الوقت/النسبة | AS12: الحاجة إلى تبرير تغيير الوحدة | AT12: مبرر تغيير الوحدة | AU12: ملاحظات فريق المشروع | AV12: الاستجابة من الإدارة | AX12: النتائج
B13: إدخال اسم الجهة | C13: إدخال اسم القطاع | D13: إدخال اسم الإدارة | E13: إدخال اسم القسم | F13: إضافة أو حذف محركات عبء العمل لمراعاة التغييرات مقارنةً بالمرحلة الثانية من خطة القوى العاملة الحكومية؛ يجب أن تكون التغييرات محدودة ومبنية على عوامل مختارة، منها إعادة الهيكلة التنظيمية أو تعديل المسؤوليات أو الملاحظات الواردة من فريق المشروع | G13: اختيار "النسبة" أو "التكرار". يُنصح في معظم الحالات باختيار طريقة الوتيرة للحساب. * للمزيد من المعلومات ، يرجى الرجوع إلى "أدلة مراجعة وتحديث محركات عبء العمل" | S13: مراجعة بيانات الحجم عند خط الأساس | T13: مراجعة بيانات الحجم عند خط الأساس | U13: مراجعة بيانات الحجم | V13: مراجعة بيانات الحجم | W13: مراجعة بيانات الحجم | X13: مراجعة بيانات الحجم | Y13: مراجعة بيانات الحجم | Z13: إدخال بيانات الحجم | AA13: مراجعة الوقت اللازم لاستكمال كل محرك عبء العمل على افتراض استكماله من قبل موظف واحد؛ يجب إجراء تغييرات محدودة فقط | AB13: تعبئة وحدة الوقت باستخدام القائمة الاختيارية | AC13: تحديث الملاحظات وتقديم تفاصيل إضافية حول محركات عبء العمل والبيانات المرتبطة بها؛ يرجى الملاحظة أن محركات عبء العمل الجديدة تتطلب تبريرًا | AP13: تقديم تبريرات للتغييرات الكبيرة في الحجم في الفترة 2023 - 2029 (مقارنةً بالمرحلة الثانية من برنامج تخطيط القوى العاملة) | AR13: تقديم تبريرات لأي تغييرات متعلقة بالوتيرة/النسبة (مقارنةً بالمرحلة الثانية من برنامج تخطيط القوى العاملة) | AT13: تقديم تبريرات لأي تغييرات في الوحدة (مقارنةً بالمرحلة الثانية من برنامج تخطيط القوى العاملة) | AX13: 2023 | AY13: 2024 | AZ13: 2025 | BA13: 2026 | BB13: 2027 | BC13: 2028 | BD13: 2029 | BE13: 2030
B14: وزارة البلدية | C14: وكيل الوزارة المساعد لشؤون الخدمات المشتركة | D14: إدارة الموارد البشرية | E14: قسم الرواتب والاجور | F14: اقفال الرواتب الشهرية لموظفى الوزارة ( اعداد و مراجعة) | G14: تكرار | I14: 24 | J14: 24 | K14: 24 | L14: 24 | M14: 24 | N14: 24 | O14: 24 | P14: 5 | Q14: أيام | S14: 24 | T14: 24 | U14: 24 | V14: 24 | W14: 24 | X14: 24 | Y14: 24 | AA14: 5 | AB14: أيام | AP14: =IF(AO14="نعم", "أضف المبررات هنا", "") | AQ14: =IF(OR(P14="", AA14=""), "", IF(P14<>AA14, "نعم", "لا")) -> لا | AR14: =IF(AQ14="نعم", "[أضف المبررات هنا]", "") | AS14: =IF(OR(Q14="", AB14=""), "", IF(Q14<>AB14, "نعم", "لا")) -> لا | AT14: =IF(AS14="نعم", "[أضف المبررات هنا]", "") | AX14: {=IFERROR(_xlfn.IFS($AB14="عدد الموظفين/الوحدة",S14*$AA14,$AB14='طريقة الحساب'!$B$2,S14*$AA14/الافتراضات!$B$27,$AB14='طريقة الحساب'!$B$3,S14*$AA14/الافتراضات!$B$26,$AB14='طريقة الحساب'!$B$4,S14*$AA14/الافتراضات!$B$28),"")} -> 0.62176166 | AY14: {=IFERROR(_xlfn.IFS($AB14="عدد الموظفين/الوحدة",T14*$AA14,$AB14='طريقة الحساب'!$B$2,T14*$AA14/الافتراضات!$B$27,$AB14='طريقة الحساب'!$B$3,T14*$AA14/الافتراضات!$B$26,$AB14='طريقة الحساب'!$B$4,T14*$AA14/الافتراضات!$B$28),"")} -> 0.62176166 | AZ14: {=IFERROR(_xlfn.IFS($AB14="عدد الموظفين/الوحدة",U14*$AA14,$AB14='طريقة الحساب'!$B$2,U14*$AA14/الافتراضات!$B$27,$AB14='طريقة الحساب'!$B$3,U14*$AA14/الافتراضات!$B$26,$AB14='طريقة الحساب'!$B$4,U14*$AA14/الافتراضات!$B$28),"")} -> 0.62176166 | BA14: {=IFERROR(_xlfn.IFS($AB14="عدد الموظفين/الوحدة",V14*$AA14,$AB14='طريقة الحساب'!$B$2,V14*$AA14/الافتراضات!$B$27,$AB14='طريقة الحساب'!$B$3,V14*$AA14/الافتراضات!$B$26,$AB14='طريقة الحساب'!$B$4,V14*$AA14/الافتراضات!$B$28),"")} -> 0.62176166 | BB14: {=IFERROR(_xlfn.IFS($AB14="عدد الموظفين/الوحدة",W14*$AA14,$AB14='طريقة الحساب'!$B$2,W14*$AA14/الافتراضات!$B$27,$AB14='طريقة الحساب'!$B$3,W14*$AA14/الافتراضات!$B$26,$AB14='طريقة الحساب'!$B$4,W14*$AA14/الافتراضات!$B$28),"")} -> 0.62176166 | BC14: {=IFERROR(_xlfn.IFS($AB14="عدد الموظفين/الوحدة",X14*$AA14,$AB14='طريقة الحساب'!$B$2,X14*$AA14/الافتراضات!$B$27,$AB14='طريقة الحساب'!$B$3,X14*$AA14/الافتراضات!$B$26,$AB14='طريقة الحساب'!$B$4,X14*$AA14/الافتراضات!$B$28),"")} -> 0.62176166 | BD14: {=IFERROR(_xlfn.IFS($AB14="عدد الموظفين/الوحدة",Y14*$AA14,$AB14='طريقة الحساب'!$B$2,Y14*$AA14/الافتراضات!$B$27,$AB14='طريقة الحساب'!$B$3,Y14*$AA14/الافتراضات!$B$26,$AB14='طريقة الحساب'!$B$4,Y14*$AA14/الافتراضات!$B$28),"")} -> 0.62176166 | BE14: {=IFERROR(_xlfn.IFS($AB14="عدد الموظفين/الوحدة",Z14*$AA14,$AB14='طريقة الحساب'!$B$2,Z14*$AA14/الافتراضات!$B$27,$AB14='طريقة الحساب'!$B$3,Z14*$AA14/الافتراضات!$B$26,$AB14='طريقة الحساب'!$B$4,Z14*$AA14/الافتراضات!$B$28),"")} -> 0
B15: وزارة البلدية | C15: وكيل الوزارة المساعد لشؤون الخدمات المشتركة | D15: إدارة الموارد البشرية | E15: قسم الرواتب والاجور | F15: اقفال ملاحق الرواتب الشهرية لموظفى الوزارة ( اعداد و مراجعة) | G15: تكرار | I15: 24 | J15: 24 | K15: 24 | L15: 24 | M15: 24 | N15: 24 | O15: 24 | P15: 3 | Q15: أيام | S15: 24 | T15: 24 | U15: 24 | V15: 24 | W15: 24 | X15: 24 | Y15: 24 | AA15: 3 | AB15: أيام | AP15: =IF(AO15="نعم", "أضف المبررات هنا", "") | AQ15: =IF(OR(P15="", AA15=""), "", IF(P15<>AA15, "نعم", "لا")) -> لا | AR15: =IF(AQ15="نعم", "[أضف المبررات هنا]", "") | AS15: =IF(OR(Q15="", AB15=""), "", IF(Q15<>AB15, "نعم", "لا")) -> لا | AT15: =IF(AS15="نعم", "[أضف المبررات هنا]", "") | AX15: {=IFERROR(_xlfn.IFS($AB15="عدد الموظفين/الوحدة",S15*$AA15,$AB15='طريقة الحساب'!$B$2,S15*$AA15/الافتراضات!$B$27,$AB15='طريقة الحساب'!$B$3,S15*$AA15/الافتراضات!$B$26,$AB15='طريقة الحساب'!$B$4,S15*$AA15/الافتراضات!$B$28),"")} -> 0.37305699 | AY15: {=IFERROR(_xlfn.IFS($AB15="عدد الموظفين/الوحدة",T15*$AA15,$AB15='طريقة الحساب'!$B$2,T15*$AA15/الافتراضات!$B$27,$AB15='طريقة الحساب'!$B$3,T15*$AA15/الافتراضات!$B$26,$AB15='طريقة الحساب'!$B$4,T15*$AA15/الافتراضات!$B$28),"")} -> 0.37305699 | AZ15: {=IFERROR(_xlfn.IFS($AB15="عدد الموظفين/الوحدة",U15*$AA15,$AB15='طريقة الحساب'!$B$2,U15*$AA15/الافتراضات!$B$27,$AB15='طريقة الحساب'!$B$3,U15*$AA15/الافتراضات!$B$26,$AB15='طريقة الحساب'!$B$4,U15*$AA15/الافتراضات!$B$28),"")} -> 0.37305699 | BA15: {=IFERROR(_xlfn.IFS($AB15="عدد الموظفين/الوحدة",V15*$AA15,$AB15='طريقة الحساب'!$B$2,V15*$AA15/الافتراضات!$B$27,$AB15='طريقة الحساب'!$B$3,V15*$AA15/الافتراضات!$B$26,$AB15='طريقة الحساب'!$B$4,V15*$AA15/الافتراضات!$B$28),"")} -> 0.37305699 | BB15: {=IFERROR(_xlfn.IFS($AB15="عدد الموظفين/الوحدة",W15*$AA15,$AB15='طريقة الحساب'!$B$2,W15*$AA15/الافتراضات!$B$27,$AB15='طريقة الحساب'!$B$3,W15*$AA15/الافتراضات!$B$26,$AB15='طريقة الحساب'!$B$4,W15*$AA15/الافتراضات!$B$28),"")} -> 0.37305699 | BC15: {=IFERROR(_xlfn.IFS($AB15="عدد الموظفين/الوحدة",X15*$AA15,$AB15='طريقة الحساب'!$B$2,X15*$AA15/الافتراضات!$B$27,$AB15='طريقة الحساب'!$B$3,X15*$AA15/الافتراضات!$B$26,$AB15='طريقة الحساب'!$B$4,X15*$AA15/الافتراضات!$B$28),"")} -> 0.37305699 | BD15: {=IFERROR(_xlfn.IFS($AB15="عدد الموظفين/الوحدة",Y15*$AA15,$AB15='طريقة الحساب'!$B$2,Y15*$AA15/الافتراضات!$B$27,$AB15='طريقة الحساب'!$B$3,Y15*$AA15/الافتراضات!$B$26,$AB15='طريقة الحساب'!$B$4,Y15*$AA15/الافتراضات!$B$28),"")} -> 0.37305699 | BE15: {=IFERROR(_xlfn.IFS($AB15="عدد الموظفين/الوحدة",Z15*$AA15,$AB15='طريقة الحساب'!$B$2,Z15*$AA15/الافتراضات!$B$27,$AB15='طريقة الحساب'!$B$3,Z15*$AA15/الافتراضات!$B$26,$AB15='طريقة الحساب'!$B$4,Z15*$AA15/الافتراضات!$B$28),"")} -> 0
B16: وزارة البلدية | C16: وكيل الوزارة المساعد لشؤون الخدمات المشتركة | D16: إدارة الموارد البشرية | E16: قسم الرواتب والاجور | F16: اعداد مشروع موازنة الباب الأول ( الرواتب و الأجور ) | G16: تكرار | I16: 1 | J16: 1 | K16: 1 | L16: 1 | M16: 1 | N16: 1 | O16: 1 | P16: 30 | Q16: أيام | S16: 1 | T16: 1 | U16: 1 | V16: 1 | W16: 1 | X16: 1 | Y16: 1 | AA16: 30 | AB16: أيام | AO16: =IF(OR(N16="", Y16=""), "", IF(N16<>Y16, "نعم", "لا")) -> لا | AP16: =IF(AO16="نعم", "أضف المبررات هنا", "") | AQ16: =IF(OR(P16="", AA16=""), "", IF(P16<>AA16, "نعم", "لا")) -> لا | AR16: =IF(AQ16="نعم", "[أضف المبررات هنا]", "") | AS16: =IF(OR(Q16="", AB16=""), "", IF(Q16<>AB16, "نعم", "لا")) -> لا | AT16: =IF(AS16="نعم", "[أضف المبررات هنا]", "") | AX16: {=IFERROR(_xlfn.IFS($AB16="عدد الموظفين/الوحدة",S16*$AA16,$AB16='طريقة الحساب'!$B$2,S16*$AA16/الافتراضات!$B$27,$AB16='طريقة الحساب'!$B$3,S16*$AA16/الافتراضات!$B$26,$AB16='طريقة الحساب'!$B$4,S16*$AA16/الافتراضات!$B$28),"")} -> 0.15544041 | AY16: {=IFERROR(_xlfn.IFS($AB16="عدد الموظفين/الوحدة",T16*$AA16,$AB16='طريقة الحساب'!$B$2,T16*$AA16/الافتراضات!$B$27,$AB16='طريقة الحساب'!$B$3,T16*$AA16/الافتراضات!$B$26,$AB16='طريقة الحساب'!$B$4,T16*$AA16/الافتراضات!$B$28),"")} -> 0.15544041 | AZ16: {=IFERROR(_xlfn.IFS($AB16="عدد الموظفين/الوحدة",U16*$AA16,$AB16='طريقة الحساب'!$B$2,U16*$AA16/الافتراضات!$B$27,$AB16='طريقة الحساب'!$B$3,U16*$AA16/الافتراضات!$B$26,$AB16='طريقة الحساب'!$B$4,U16*$AA16/الافتراضات!$B$28),"")} -> 0.15544041 | BA16: {=IFERROR(_xlfn.IFS($AB16="عدد الموظفين/الوحدة",V16*$AA16,$AB16='طريقة الحساب'!$B$2,V16*$AA16/الافتراضات!$B$27,$AB16='طريقة الحساب'!$B$3,V16*$AA16/الافتراضات!$B$26,$AB16='طريقة الحساب'!$B$4,V16*$AA16/الافتراضات!$B$28),"")} -> 0.15544041 | BB16: {=IFERROR(_xlfn.IFS($AB16="عدد الموظفين/الوحدة",W16*$AA16,$AB16='طريقة الحساب'!$B$2,W16*$AA16/الافتراضات!$B$27,$AB16='طريقة الحساب'!$B$3,W16*$AA16/الافتراضات!$B$26,$AB16='طريقة الحساب'!$B$4,W16*$AA16/الافتراضات!$B$28),"")} -> 0.15544041 | BC16: {=IFERROR(_xlfn.IFS($AB16="عدد الموظفين/الوحدة",X16*$AA16,$AB16='طريقة الحساب'!$B$2,X16*$AA16/الافتراضات!$B$27,$AB16='طريقة الحساب'!$B$3,X16*$AA16/الافتراضات!$B$26,$AB16='طريقة الحساب'!$B$4,X16*$AA16/الافتراضات!$B$28),"")} -> 0.15544041 | BD16: {=IFERROR(_xlfn.IFS($AB16="عدد الموظفين/الوحدة",Y16*$AA16,$AB16='طريقة الحساب'!$B$2,Y16*$AA16/الافتراضات!$B$27,$AB16='طريقة الحساب'!$B$3,Y16*$AA16/الافتراضات!$B$26,$AB16='طريقة الحساب'!$B$4,Y16*$AA16/الافتراضات!$B$28),"")} -> 0.15544041 | BE16: {=IFERROR(_xlfn.IFS($AB16="عدد الموظفين/الوحدة",Z16*$AA16,$AB16='طريقة الحساب'!$B$2,Z16*$AA16/الافتراضات!$B$27,$AB16='طريقة الحساب'!$B$3,Z16*$AA16/الافتراضات!$B$26,$AB16='طريقة الحساب'!$B$4,Z16*$AA16/الافتراضات!$B$28),"")} -> 0
B17: وزارة البلدية | C17: وكيل الوزارة المساعد لشؤون الخدمات المشتركة | D17: إدارة الموارد البشرية | E17: قسم الرواتب والاجور | F17: الطلبات المتممة لاعتماد مشروع الموازنة و الاجتماعات المتعلقة بها | G17: تكرار | I17: 5 | J17: 5 | K17: 5 | L17: 5 | M17: 5 | N17: 5 | O17: 5 | P17: 60 | Q17: أيام | S17: 5 | T17: 5 | U17: 5 | V17: 5 | W17: 5 | X17: 5 | Y17: 5 | AA17: 60 | AB17: أيام | AO17: =IF(OR(N17="", Y17=""), "", IF(N17<>Y17, "نعم", "لا")) -> لا | AP17: =IF(AO17="نعم", "أضف المبررات هنا", "") | AQ17: =IF(OR(P17="", AA17=""), "", IF(P17<>AA17, "نعم", "لا")) -> لا | AR17: =IF(AQ17="نعم", "[أضف المبررات هنا]", "") | AS17: =IF(OR(Q17="", AB17=""), "", IF(Q17<>AB17, "نعم", "لا")) -> لا | AT17: =IF(AS17="نعم", "[أضف المبررات هنا]", "") | AX17: {=IFERROR(_xlfn.IFS($AB17="عدد الموظفين/الوحدة",S17*$AA17,$AB17='طريقة الحساب'!$B$2,S17*$AA17/الافتراضات!$B$27,$AB17='طريقة الحساب'!$B$3,S17*$AA17/الافتراضات!$B$26,$AB17='طريقة الحساب'!$B$4,S17*$AA17/الافتراضات!$B$28),"")} -> 1.5544041 | AY17: {=IFERROR(_xlfn.IFS($AB17="عدد الموظفين/الوحدة",T17*$AA17,$AB17='طريقة الحساب'!$B$2,T17*$AA17/الافتراضات!$B$27,$AB17='طريقة الحساب'!$B$3,T17*$AA17/الافتراضات!$B$26,$AB17='طريقة الحساب'!$B$4,T17*$AA17/الافتراضات!$B$28),"")} -> 1.5544041 | AZ17: {=IFERROR(_xlfn.IFS($AB17="عدد الموظفين/الوحدة",U17*$AA17,$AB17='طريقة الحساب'!$B$2,U17*$AA17/الافتراضات!$B$27,$AB17='طريقة الحساب'!$B$3,U17*$AA17/الافتراضات!$B$26,$AB17='طريقة الحساب'!$B$4,U17*$AA17/الافتراضات!$B$28),"")} -> 1.5544041 | BA17: {=IFERROR(_xlfn.IFS($AB17="عدد الموظفين/الوحدة",V17*$AA17,$AB17='طريقة الحساب'!$B$2,V17*$AA17/الافتراضات!$B$27,$AB17='طريقة الحساب'!$B$3,V17*$AA17/الافتراضات!$B$26,$AB17='طريقة الحساب'!$B$4,V17*$AA17/الافتراضات!$B$28),"")} -> 1.5544041 | BB17: {=IFERROR(_xlfn.IFS($AB17="عدد الموظفين/الوحدة",W17*$AA17,$AB17='طريقة الحساب'!$B$2,W17*$AA17/الافتراضات!$B$27,$AB17='طريقة الحساب'!$B$3,W17*$AA17/الافتراضات!$B$26,$AB17='طريقة الحساب'!$B$4,W17*$AA17/الافتراضات!$B$28),"")} -> 1.5544041 | BC17: {=IFERROR(_xlfn.IFS($AB17="عدد الموظفين/الوحدة",X17*$AA17,$AB17='طريقة الحساب'!$B$2,X17*$AA17/الافتراضات!$B$27,$AB17='طريقة الحساب'!$B$3,X17*$AA17/الافتراضات!$B$26,$AB17='طريقة الحساب'!$B$4,X17*$AA17/الافتراضات!$B$28),"")} -> 1.5544041 | BD17: {=IFERROR(_xlfn.IFS($AB17="عدد الموظفين/الوحدة",Y17*$AA17,$AB17='طريقة الحساب'!$B$2,Y17*$AA17/الافتراضات!$B$27,$AB17='طريقة الحساب'!$B$3,Y17*$AA17/الافتراضات!$B$26,$AB17='طريقة الحساب'!$B$4,Y17*$AA17/الافتراضات!$B$28),"")} -> 1.5544041 | BE17: {=IFERROR(_xlfn.IFS($AB17="عدد الموظفين/الوحدة",Z17*$AA17,$AB17='طريقة الحساب'!$B$2,Z17*$AA17/الافتراضات!$B$27,$AB17='طريقة الحساب'!$B$3,Z17*$AA17/الافتراضات!$B$26,$AB17='طريقة الحساب'!$B$4,Z17*$AA17/الافتراضات!$B$28),"")} -> 0
B18: وزارة البلدية | C18: وكيل الوزارة المساعد لشؤون الخدمات المشتركة | D18: إدارة الموارد البشرية | E18: قسم الرواتب والاجور | F18: عملية تسويات مستحقات نهاية الخدمة | G18: تكرار | I18: 348 | J18: 400 | K18: 430 | L18: 460 | M18: 490 | N18: 520 | O18: 520 | P18: 1 | Q18: أيام | S18: 348 | T18: 400 | U18: 430 | V18: 460 | W18: 490 | X18: 520 | Y18: 520 | AA18: 1 | AB18: أيام | AO18: =IF(OR(N18="", Y18=""), "", IF(N18<>Y18, "نعم", "لا")) -> لا | AP18: =IF(AO18="نعم", "أضف المبررات هنا", "") | AQ18: =IF(OR(P18="", AA18=""), "", IF(P18<>AA18, "نعم", "لا")) -> لا | AR18: =IF(AQ18="نعم", "[أضف المبررات هنا]", "") | AS18: =IF(OR(Q18="", AB18=""), "", IF(Q18<>AB18, "نعم", "لا")) -> لا | AT18: =IF(AS18="نعم", "[أضف المبررات هنا]", "") | AX18: {=IFERROR(_xlfn.IFS($AB18="عدد الموظفين/الوحدة",S18*$AA18,$AB18='طريقة الحساب'!$B$2,S18*$AA18/الافتراضات!$B$27,$AB18='طريقة الحساب'!$B$3,S18*$AA18/الافتراضات!$B$26,$AB18='طريقة الحساب'!$B$4,S18*$AA18/الافتراضات!$B$28),"")} -> 1.8031088 | AY18: {=IFERROR(_xlfn.IFS($AB18="عدد الموظفين/الوحدة",T18*$AA18,$AB18='طريقة الحساب'!$B$2,T18*$AA18/الافتراضات!$B$27,$AB18='طريقة الحساب'!$B$3,T18*$AA18/الافتراضات!$B$26,$AB18='طريقة الحساب'!$B$4,T18*$AA18/الافتراضات!$B$28),"")} -> 2.0725389 | AZ18: {=IFERROR(_xlfn.IFS($AB18="عدد الموظفين/الوحدة",U18*$AA18,$AB18='طريقة الحساب'!$B$2,U18*$AA18/الافتراضات!$B$27,$AB18='طريقة الحساب'!$B$3,U18*$AA18/الافتراضات!$B$26,$AB18='طريقة الحساب'!$B$4,U18*$AA18/الافتراضات!$B$28),"")} -> 2.2279793 | BA18: {=IFERROR(_xlfn.IFS($AB18="عدد الموظفين/الوحدة",V18*$AA18,$AB18='طريقة الحساب'!$B$2,V18*$AA18/الافتراضات!$B$27,$AB18='طريقة الحساب'!$B$3,V18*$AA18/الافتراضات!$B$26,$AB18='طريقة الحساب'!$B$4,V18*$AA18/الافتراضات!$B$28),"")} -> 2.3834197 | BB18: {=IFERROR(_xlfn.IFS($AB18="عدد الموظفين/الوحدة",W18*$AA18,$AB18='طريقة الحساب'!$B$2,W18*$AA18/الافتراضات!$B$27,$AB18='طريقة الحساب'!$B$3,W18*$AA18/الافتراضات!$B$26,$AB18='طريقة الحساب'!$B$4,W18*$AA18/الافتراضات!$B$28),"")} -> 2.5388601 | BC18: {=IFERROR(_xlfn.IFS($AB18="عدد الموظفين/الوحدة",X18*$AA18,$AB18='طريقة الحساب'!$B$2,X18*$AA18/الافتراضات!$B$27,$AB18='طريقة الحساب'!$B$3,X18*$AA18/الافتراضات!$B$26,$AB18='طريقة الحساب'!$B$4,X18*$AA18/الافتراضات!$B$28),"")} -> 2.6943005 | BD18: {=IFERROR(_xlfn.IFS($AB18="عدد الموظفين/الوحدة",Y18*$AA18,$AB18='طريقة الحساب'!$B$2,Y18*$AA18/الافتراضات!$B$27,$AB18='طريقة الحساب'!$B$3,Y18*$AA18/الافتراضات!$B$26,$AB18='طريقة الحساب'!$B$4,Y18*$AA18/الافتراضات!$B$28),"")} -> 2.6943005 | BE18: {=IFERROR(_xlfn.IFS($AB18="عدد الموظفين/الوحدة",Z18*$AA18,$AB18='طريقة الحساب'!$B$2,Z18*$AA18/الافتراضات!$B$27,$AB18='طريقة الحساب'!$B$3,Z18*$AA18/الافتراضات!$B$26,$AB18='طريقة الحساب'!$B$4,Z18*$AA18/الافتراضات!$B$28),"")} -> 0
B19: وزارة البلدية | C19: وكيل الوزارة المساعد لشؤون الخدمات المشتركة | D19: إدارة الموارد البشرية | E19: قسم الرواتب والاجور | F19: تذاكر سفر للموظفين | G19: تكرار | I19: 2918 | J19: 4200 | K19: 4200 | L19: 4200 | M19: 4200 | N19: 4200 | O19: 4200 | P19: 10 | Q19: دقائق | S19: 2918 | T19: 4200 | U19: 4200 | V19: 4200 | W19: 4200 | X19: 4200 | Y19: 4200 | AA19: 10 | AB19: دقائق | AO19: =IF(OR(N19="", Y19=""), "", IF(N19<>Y19, "نعم", "لا")) -> لا | AP19: =IF(AO19="نعم", "أضف المبررات هنا", "") | AQ19: =IF(OR(P19="", AA19=""), "", IF(P19<>AA19, "نعم", "لا")) -> لا | AR19: =IF(AQ19="نعم", "[أضف المبررات هنا]", "") | AS19: =IF(OR(Q19="", AB19=""), "", IF(Q19<>AB19, "نعم", "لا")) -> لا | AT19: =IF(AS19="نعم", "[أضف المبررات هنا]", "") | AX19: {=IFERROR(_xlfn.IFS($AB19="عدد الموظفين/الوحدة",S19*$AA19,$AB19='طريقة الحساب'!$B$2,S19*$AA19/الافتراضات!$B$27,$AB19='طريقة الحساب'!$B$3,S19*$AA19/الافتراضات!$B$26,$AB19='طريقة الحساب'!$B$4,S19*$AA19/الافتراضات!$B$28),"")} -> 0.49075961 | AY19: {=IFERROR(_xlfn.IFS($AB19="عدد الموظفين/الوحدة",T19*$AA19,$AB19='طريقة الحساب'!$B$2,T19*$AA19/الافتراضات!$B$27,$AB19='طريقة الحساب'!$B$3,T19*$AA19/الافتراضات!$B$26,$AB19='طريقة الحساب'!$B$4,T19*$AA19/الافتراضات!$B$28),"")} -> 0.70637092 | AZ19: {=IFERROR(_xlfn.IFS($AB19="عدد الموظفين/الوحدة",U19*$AA19,$AB19='طريقة الحساب'!$B$2,U19*$AA19/الافتراضات!$B$27,$AB19='طريقة الحساب'!$B$3,U19*$AA19/الافتراضات!$B$26,$AB19='طريقة الحساب'!$B$4,U19*$AA19/الافتراضات!$B$28),"")} -> 0.70637092 | BA19: {=IFERROR(_xlfn.IFS($AB19="عدد الموظفين/الوحدة",V19*$AA19,$AB19='طريقة الحساب'!$B$2,V19*$AA19/الافتراضات!$B$27,$AB19='طريقة الحساب'!$B$3,V19*$AA19/الافتراضات!$B$26,$AB19='طريقة الحساب'!$B$4,V19*$AA19/الافتراضات!$B$28),"")} -> 0.70637092 | BB19: {=IFERROR(_xlfn.IFS($AB19="عدد الموظفين/الوحدة",W19*$AA19,$AB19='طريقة الحساب'!$B$2,W19*$AA19/الافتراضات!$B$27,$AB19='طريقة الحساب'!$B$3,W19*$AA19/الافتراضات!$B$26,$AB19='طريقة الحساب'!$B$4,W19*$AA19/الافتراضات!$B$28),"")} -> 0.70637092 | BC19: {=IFERROR(_xlfn.IFS($AB19="عدد الموظفين/الوحدة",X19*$AA19,$AB19='طريقة الحساب'!$B$2,X19*$AA19/الافتراضات!$B$27,$AB19='طريقة الحساب'!$B$3,X19*$AA19/الافتراضات!$B$26,$AB19='طريقة الحساب'!$B$4,X19*$AA19/الافتراضات!$B$28),"")} -> 0.70637092 | BD19: {=IFERROR(_xlfn.IFS($AB19="عدد الموظفين/الوحدة",Y19*$AA19,$AB19='طريقة الحساب'!$B$2,Y19*$AA19/الافتراضات!$B$27,$AB19='طريقة الحساب'!$B$3,Y19*$AA19/الافتراضات!$B$26,$AB19='طريقة الحساب'!$B$4,Y19*$AA19/الافتراضات!$B$28),"")} -> 0.70637092 | BE19: {=IFERROR(_xlfn.IFS($AB19="عدد الموظفين/الوحدة",Z19*$AA19,$AB19='طريقة الحساب'!$B$2,Z19*$AA19/الافتراضات!$B$27,$AB19='طريقة الحساب'!$B$3,Z19*$AA19/الافتراضات!$B$26,$AB19='طريقة الحساب'!$B$4,Z19*$AA19/الافتراضات!$B$28),"")} -> 0
B20: وزارة البلدية | C20: وكيل الوزارة المساعد لشؤون الخدمات المشتركة | D20: إدارة الموارد البشرية | E20: قسم الرواتب والاجور | F20: معاملات المهمات الرسمية | G20: تكرار | I20: 430 | J20: 800 | K20: 785.61096 | L20: 967.00217 | M20: 1036.4068 | N20: 1219.4112 | O20: 1219.4112 | P20: 1 | Q20: ساعات | S20: 430 | T20: 800 | U20: 785.61096 | V20: 967.00217 | W20: 1036.4068 | X20: 1219.4112 | Y20: 1219.4112 | AA20: 1 | AB20: ساعات | AO20: =IF(OR(N20="", Y20=""), "", IF(N20<>Y20, "نعم", "لا")) -> لا | AP20: =IF(AO20="نعم", "أضف المبررات هنا", "") | AQ20: =IF(OR(P20="", AA20=""), "", IF(P20<>AA20, "نعم", "لا")) -> لا | AR20: =IF(AQ20="نعم", "[أضف المبررات هنا]", "") | AS20: =IF(OR(Q20="", AB20=""), "", IF(Q20<>AB20, "نعم", "لا")) -> لا | AT20: =IF(AS20="نعم", "[أضف المبررات هنا]", "") | AX20: {=IFERROR(_xlfn.IFS($AB20="عدد الموظفين/الوحدة",S20*$AA20,$AB20='طريقة الحساب'!$B$2,S20*$AA20/الافتراضات!$B$27,$AB20='طريقة الحساب'!$B$3,S20*$AA20/الافتراضات!$B$26,$AB20='طريقة الحساب'!$B$4,S20*$AA20/الافتراضات!$B$28),"")} -> 0.43391357 | AY20: {=IFERROR(_xlfn.IFS($AB20="عدد الموظفين/الوحدة",T20*$AA20,$AB20='طريقة الحساب'!$B$2,T20*$AA20/الافتراضات!$B$27,$AB20='طريقة الحساب'!$B$3,T20*$AA20/الافتراضات!$B$26,$AB20='طريقة الحساب'!$B$4,T20*$AA20/الافتراضات!$B$28),"")} -> 0.80728105 | AZ20: {=IFERROR(_xlfn.IFS($AB20="عدد الموظفين/الوحدة",U20*$AA20,$AB20='طريقة الحساب'!$B$2,U20*$AA20/الافتراضات!$B$27,$AB20='طريقة الحساب'!$B$3,U20*$AA20/الافتراضات!$B$26,$AB20='طريقة الحساب'!$B$4,U20*$AA20/الافتراضات!$B$28),"")} -> 0.79276105 | BA20: {=IFERROR(_xlfn.IFS($AB20="عدد الموظفين/الوحدة",V20*$AA20,$AB20='طريقة الحساب'!$B$2,V20*$AA20/الافتراضات!$B$27,$AB20='طريقة الحساب'!$B$3,V20*$AA20/الافتراضات!$B$26,$AB20='طريقة الحساب'!$B$4,V20*$AA20/الافتراضات!$B$28),"")} -> 0.97580316 | BB20: {=IFERROR(_xlfn.IFS($AB20="عدد الموظفين/الوحدة",W20*$AA20,$AB20='طريقة الحساب'!$B$2,W20*$AA20/الافتراضات!$B$27,$AB20='طريقة الحساب'!$B$3,W20*$AA20/الافتراضات!$B$26,$AB20='طريقة الحساب'!$B$4,W20*$AA20/الافتراضات!$B$28),"")} -> 1.0458395 | BC20: {=IFERROR(_xlfn.IFS($AB20="عدد الموظفين/الوحدة",X20*$AA20,$AB20='طريقة الحساب'!$B$2,X20*$AA20/الافتراضات!$B$27,$AB20='طريقة الحساب'!$B$3,X20*$AA20/الافتراضات!$B$26,$AB20='طريقة الحساب'!$B$4,X20*$AA20/الافتراضات!$B$28),"")} -> 1.2305094 | BD20: {=IFERROR(_xlfn.IFS($AB20="عدد الموظفين/الوحدة",Y20*$AA20,$AB20='طريقة الحساب'!$B$2,Y20*$AA20/الافتراضات!$B$27,$AB20='طريقة الحساب'!$B$3,Y20*$AA20/الافتراضات!$B$26,$AB20='طريقة الحساب'!$B$4,Y20*$AA20/الافتراضات!$B$28),"")} -> 1.2305094 | BE20: {=IFERROR(_xlfn.IFS($AB20="عدد الموظفين/الوحدة",Z20*$AA20,$AB20='طريقة الحساب'!$B$2,Z20*$AA20/الافتراضات!$B$27,$AB20='طريقة الحساب'!$B$3,Z20*$AA20/الافتراضات!$B$26,$AB20='طريقة الحساب'!$B$4,Z20*$AA20/الافتراضات!$B$28),"")} -> 0
B21: وزارة البلدية | C21: وكيل الوزارة المساعد لشؤون الخدمات المشتركة | D21: إدارة الموارد البشرية | E21: قسم الرواتب والاجور | F21: معاملات السلف | G21: تكرار | I21: 4571 | J21: 1000 | K21: 1050 | L21: 1102.5 | M21: 1157.625 | N21: 1215.5063 | O21: 1215.5063 | P21: 0.5 | Q21: ساعات | S21: 4571 | T21: 1000 | U21: 1050 | V21: 1102.5 | W21: 1157.625 | X21: 1215.5063 | Y21: 1215.5063 | AA21: 0.5 | AB21: ساعات | AO21: =IF(OR(N21="", Y21=""), "", IF(N21<>Y21, "نعم", "لا")) -> لا | AP21: =IF(AO21="نعم", "أضف المبررات هنا", "") | AQ21: =IF(OR(P21="", AA21=""), "", IF(P21<>AA21, "نعم", "لا")) -> لا | AR21: =IF(AQ21="نعم", "[أضف المبررات هنا]", "") | AS21: =IF(OR(Q21="", AB21=""), "", IF(Q21<>AB21, "نعم", "لا")) -> لا | AT21: =IF(AS21="نعم", "[أضف المبررات هنا]", "") | AX21: {=IFERROR(_xlfn.IFS($AB21="عدد الموظفين/الوحدة",S21*$AA21,$AB21='طريقة الحساب'!$B$2,S21*$AA21/الافتراضات!$B$27,$AB21='طريقة الحساب'!$B$3,S21*$AA21/الافتراضات!$B$26,$AB21='طريقة الحساب'!$B$4,S21*$AA21/الافتراضات!$B$28),"")} -> 2.3063011 | AY21: {=IFERROR(_xlfn.IFS($AB21="عدد الموظفين/الوحدة",T21*$AA21,$AB21='طريقة الحساب'!$B$2,T21*$AA21/الافتراضات!$B$27,$AB21='طريقة الحساب'!$B$3,T21*$AA21/الافتراضات!$B$26,$AB21='طريقة الحساب'!$B$4,T21*$AA21/الافتراضات!$B$28),"")} -> 0.50455066 | AZ21: {=IFERROR(_xlfn.IFS($AB21="عدد الموظفين/الوحدة",U21*$AA21,$AB21='طريقة الحساب'!$B$2,U21*$AA21/الافتراضات!$B$27,$AB21='طريقة الحساب'!$B$3,U21*$AA21/الافتراضات!$B$26,$AB21='طريقة الحساب'!$B$4,U21*$AA21/الافتراضات!$B$28),"")} -> 0.52977819 | BA21: {=IFERROR(_xlfn.IFS($AB21="عدد الموظفين/الوحدة",V21*$AA21,$AB21='طريقة الحساب'!$B$2,V21*$AA21/الافتراضات!$B$27,$AB21='طريقة الحساب'!$B$3,V21*$AA21/الافتراضات!$B$26,$AB21='طريقة الحساب'!$B$4,V21*$AA21/الافتراضات!$B$28),"")} -> 0.5562671 | BB21: {=IFERROR(_xlfn.IFS($AB21="عدد الموظفين/الوحدة",W21*$AA21,$AB21='طريقة الحساب'!$B$2,W21*$AA21/الافتراضات!$B$27,$AB21='طريقة الحساب'!$B$3,W21*$AA21/الافتراضات!$B$26,$AB21='طريقة الحساب'!$B$4,W21*$AA21/الافتراضات!$B$28),"")} -> 0.58408046 | BC21: {=IFERROR(_xlfn.IFS($AB21="عدد الموظفين/الوحدة",X21*$AA21,$AB21='طريقة الحساب'!$B$2,X21*$AA21/الافتراضات!$B$27,$AB21='طريقة الحساب'!$B$3,X21*$AA21/الافتراضات!$B$26,$AB21='طريقة الحساب'!$B$4,X21*$AA21/الافتراضات!$B$28),"")} -> 0.61328448 | BD21: {=IFERROR(_xlfn.IFS($AB21="عدد الموظفين/الوحدة",Y21*$AA21,$AB21='طريقة الحساب'!$B$2,Y21*$AA21/الافتراضات!$B$27,$AB21='طريقة الحساب'!$B$3,Y21*$AA21/الافتراضات!$B$26,$AB21='طريقة الحساب'!$B$4,Y21*$AA21/الافتراضات!$B$28),"")} -> 0.61328448 | BE21: {=IFERROR(_xlfn.IFS($AB21="عدد الموظفين/الوحدة",Z21*$AA21,$AB21='طريقة الحساب'!$B$2,Z21*$AA21/الافتراضات!$B$27,$AB21='طريقة الحساب'!$B$3,Z21*$AA21/الافتراضات!$B$26,$AB21='طريقة الحساب'!$B$4,Z21*$AA21/الافتراضات!$B$28),"")} -> 0
B22: وزارة البلدية | C22: وكيل الوزارة المساعد لشؤون الخدمات المشتركة | D22: إدارة الموارد البشرية | E22: قسم الرواتب والاجور | F22: معاملات المنح | G22: تكرار | I22: 4571 | J22: 5000 | K22: 5250 | L22: 5512.5 | M22: 5788.125 | N22: 6077.5312 | O22: 6077.5312 | P22: 0.5 | Q22: ساعات | S22: 4571 | T22: 5000 | U22: 5250 | V22: 5512.5 | W22: 5788.125 | X22: 6077.5312 | Y22: 6077.5312 | AA22: 0.5 | AB22: ساعات | AO22: =IF(OR(N22="", Y22=""), "", IF(N22<>Y22, "نعم", "لا")) -> لا | AP22: =IF(AO22="نعم", "أضف المبررات هنا", "") | AQ22: =IF(OR(P22="", AA22=""), "", IF(P22<>AA22, "نعم", "لا")) -> لا | AR22: =IF(AQ22="نعم", "[أضف المبررات هنا]", "") | AS22: =IF(OR(Q22="", AB22=""), "", IF(Q22<>AB22, "نعم", "لا")) -> لا | AT22: =IF(AS22="نعم", "[أضف المبررات هنا]", "") | AX22: {=IFERROR(_xlfn.IFS($AB22="عدد الموظفين/الوحدة",S22*$AA22,$AB22='طريقة الحساب'!$B$2,S22*$AA22/الافتراضات!$B$27,$AB22='طريقة الحساب'!$B$3,S22*$AA22/الافتراضات!$B$26,$AB22='طريقة الحساب'!$B$4,S22*$AA22/الافتراضات!$B$28),"")} -> 2.3063011 | AY22: {=IFERROR(_xlfn.IFS($AB22="عدد الموظفين/الوحدة",T22*$AA22,$AB22='طريقة الحساب'!$B$2,T22*$AA22/الافتراضات!$B$27,$AB22='طريقة الحساب'!$B$3,T22*$AA22/الافتراضات!$B$26,$AB22='طريقة الحساب'!$B$4,T22*$AA22/الافتراضات!$B$28),"")} -> 2.5227533 | AZ22: {=IFERROR(_xlfn.IFS($AB22="عدد الموظفين/الوحدة",U22*$AA22,$AB22='طريقة الحساب'!$B$2,U22*$AA22/الافتراضات!$B$27,$AB22='طريقة الحساب'!$B$3,U22*$AA22/الافتراضات!$B$26,$AB22='طريقة الحساب'!$B$4,U22*$AA22/الافتراضات!$B$28),"")} -> 2.648891 | BA22: {=IFERROR(_xlfn.IFS($AB22="عدد الموظفين/الوحدة",V22*$AA22,$AB22='طريقة الحساب'!$B$2,V22*$AA22/الافتراضات!$B$27,$AB22='طريقة الحساب'!$B$3,V22*$AA22/الافتراضات!$B$26,$AB22='طريقة الحساب'!$B$4,V22*$AA22/الافتراضات!$B$28),"")} -> 2.7813355 | BB22: {=IFERROR(_xlfn.IFS($AB22="عدد الموظفين/الوحدة",W22*$AA22,$AB22='طريقة الحساب'!$B$2,W22*$AA22/الافتراضات!$B$27,$AB22='طريقة الحساب'!$B$3,W22*$AA22/الافتراضات!$B$26,$AB22='طريقة الحساب'!$B$4,W22*$AA22/الافتراضات!$B$28),"")} -> 2.9204023 | BC22: {=IFERROR(_xlfn.IFS($AB22="عدد الموظفين/الوحدة",X22*$AA22,$AB22='طريقة الحساب'!$B$2,X22*$AA22/الافتراضات!$B$27,$AB22='طريقة الحساب'!$B$3,X22*$AA22/الافتراضات!$B$26,$AB22='طريقة الحساب'!$B$4,X22*$AA22/الافتراضات!$B$28),"")} -> 3.0664224 | BD22: {=IFERROR(_xlfn.IFS($AB22="عدد الموظفين/الوحدة",Y22*$AA22,$AB22='طريقة الحساب'!$B$2,Y22*$AA22/الافتراضات!$B$27,$AB22='طريقة الحساب'!$B$3,Y22*$AA22/الافتراضات!$B$26,$AB22='طريقة الحساب'!$B$4,Y22*$AA22/الافتراضات!$B$28),"")} -> 3.0664224 | BE22: {=IFERROR(_xlfn.IFS($AB22="عدد الموظفين/الوحدة",Z22*$AA22,$AB22='طريقة الحساب'!$B$2,Z22*$AA22/الافتراضات!$B$27,$AB22='طريقة الحساب'!$B$3,Z22*$AA22/الافتراضات!$B$26,$AB22='طريقة الحساب'!$B$4,Z22*$AA22/الافتراضات!$B$28),"")} -> 0
B23: وزارة البلدية | C23: وكيل الوزارة المساعد لشؤون الخدمات المشتركة | D23: إدارة الموارد البشرية | E23: قسم الرواتب والاجور | F23: التدقيق على التعيينات | G23: تكرار | I23: 548 | J23: 700 | K23: 735 | L23: 771.75 | M23: 810.3375 | N23: 850.85438 | O23: 850.85438 | P23: 15 | Q23: دقائق | S23: 548 | T23: 700 | U23: 735 | V23: 771.75 | W23: 810.3375 | X23: 850.85438 | Y23: 850.85438 | AA23: 15 | AB23: دقائق | AO23: =IF(OR(N23="", Y23=""), "", IF(N23<>Y23, "نعم", "لا")) -> لا | AP23: =IF(AO23="نعم", "أضف المبررات هنا", "") | AQ23: =IF(OR(P23="", AA23=""), "", IF(P23<>AA23, "نعم", "لا")) -> لا | AR23: =IF(AQ23="نعم", "[أضف المبررات هنا]", "") | AS23: =IF(OR(Q23="", AB23=""), "", IF(Q23<>AB23, "نعم", "لا")) -> لا | AT23: =IF(AS23="نعم", "[أضف المبررات هنا]", "") | AX23: {=IFERROR(_xlfn.IFS($AB23="عدد الموظفين/الوحدة",S23*$AA23,$AB23='طريقة الحساب'!$B$2,S23*$AA23/الافتراضات!$B$27,$AB23='طريقة الحساب'!$B$3,S23*$AA23/الافتراضات!$B$26,$AB23='طريقة الحساب'!$B$4,S23*$AA23/الافتراضات!$B$28),"")} -> 0.13824688 | AY23: {=IFERROR(_xlfn.IFS($AB23="عدد الموظفين/الوحدة",T23*$AA23,$AB23='طريقة الحساب'!$B$2,T23*$AA23/الافتراضات!$B$27,$AB23='طريقة الحساب'!$B$3,T23*$AA23/الافتراضات!$B$26,$AB23='طريقة الحساب'!$B$4,T23*$AA23/الافتراضات!$B$28),"")} -> 0.17659273 | AZ23: {=IFERROR(_xlfn.IFS($AB23="عدد الموظفين/الوحدة",U23*$AA23,$AB23='طريقة الحساب'!$B$2,U23*$AA23/الافتراضات!$B$27,$AB23='طريقة الحساب'!$B$3,U23*$AA23/الافتراضات!$B$26,$AB23='طريقة الحساب'!$B$4,U23*$AA23/الافتراضات!$B$28),"")} -> 0.18542237 | BA23: {=IFERROR(_xlfn.IFS($AB23="عدد الموظفين/الوحدة",V23*$AA23,$AB23='طريقة الحساب'!$B$2,V23*$AA23/الافتراضات!$B$27,$AB23='طريقة الحساب'!$B$3,V23*$AA23/الافتراضات!$B$26,$AB23='طريقة الحساب'!$B$4,V23*$AA23/الافتراضات!$B$28),"")} -> 0.19469349 | BB23: {=IFERROR(_xlfn.IFS($AB23="عدد الموظفين/الوحدة",W23*$AA23,$AB23='طريقة الحساب'!$B$2,W23*$AA23/الافتراضات!$B$27,$AB23='طريقة الحساب'!$B$3,W23*$AA23/الافتراضات!$B$26,$AB23='طريقة الحساب'!$B$4,W23*$AA23/الافتراضات!$B$28),"")} -> 0.20442816 | BC23: {=IFERROR(_xlfn.IFS($AB23="عدد الموظفين/الوحدة",X23*$AA23,$AB23='طريقة الحساب'!$B$2,X23*$AA23/الافتراضات!$B$27,$AB23='طريقة الحساب'!$B$3,X23*$AA23/الافتراضات!$B$26,$AB23='طريقة الحساب'!$B$4,X23*$AA23/الافتراضات!$B$28),"")} -> 0.21464957 | BD23: {=IFERROR(_xlfn.IFS($AB23="عدد الموظفين/الوحدة",Y23*$AA23,$AB23='طريقة الحساب'!$B$2,Y23*$AA23/الافتراضات!$B$27,$AB23='طريقة الحساب'!$B$3,Y23*$AA23/الافتراضات!$B$26,$AB23='طريقة الحساب'!$B$4,Y23*$AA23/الافتراضات!$B$28),"")} -> 0.21464957 | BE23: {=IFERROR(_xlfn.IFS($AB23="عدد الموظفين/الوحدة",Z23*$AA23,$AB23='طريقة الحساب'!$B$2,Z23*$AA23/الافتراضات!$B$27,$AB23='طريقة الحساب'!$B$3,Z23*$AA23/الافتراضات!$B$26,$AB23='طريقة الحساب'!$B$4,Z23*$AA23/الافتراضات!$B$28),"")} -> 0
B24: وزارة البلدية | C24: وكيل الوزارة المساعد لشؤون الخدمات المشتركة | D24: إدارة الموارد البشرية | E24: قسم الرواتب والاجور | F24: معاملات تقاعد القطريين | G24: تكرار | I24: 278.4 | J24: 340 | K24: 364 | L24: 388 | M24: 412 | N24: 436 | O24: 436 | P24: 1 | Q24: ساعات | S24: 278.4 | T24: 340 | U24: 364 | V24: 388 | W24: 412 | X24: 436 | Y24: 436 | AA24: 1 | AB24: ساعات | AO24: =IF(OR(N24="", Y24=""), "", IF(N24<>Y24, "نعم", "لا")) -> لا | AP24: =IF(AO24="نعم", "أضف المبررات هنا", "") | AQ24: =IF(OR(P24="", AA24=""), "", IF(P24<>AA24, "نعم", "لا")) -> لا | AR24: =IF(AQ24="نعم", "[أضف المبررات هنا]", "") | AS24: =IF(OR(Q24="", AB24=""), "", IF(Q24<>AB24, "نعم", "لا")) -> لا | AT24: =IF(AS24="نعم", "[أضف المبررات هنا]", "") | AX24: {=IFERROR(_xlfn.IFS($AB24="عدد الموظفين/الوحدة",S24*$AA24,$AB24='طريقة الحساب'!$B$2,S24*$AA24/الافتراضات!$B$27,$AB24='طريقة الحساب'!$B$3,S24*$AA24/الافتراضات!$B$26,$AB24='طريقة الحساب'!$B$4,S24*$AA24/الافتراضات!$B$28),"")} -> 0.28093381 | AY24: {=IFERROR(_xlfn.IFS($AB24="عدد الموظفين/الوحدة",T24*$AA24,$AB24='طريقة الحساب'!$B$2,T24*$AA24/الافتراضات!$B$27,$AB24='طريقة الحساب'!$B$3,T24*$AA24/الافتراضات!$B$26,$AB24='طريقة الحساب'!$B$4,T24*$AA24/الافتراضات!$B$28),"")} -> 0.34309445 | AZ24: {=IFERROR(_xlfn.IFS($AB24="عدد الموظفين/الوحدة",U24*$AA24,$AB24='طريقة الحساب'!$B$2,U24*$AA24/الافتراضات!$B$27,$AB24='طريقة الحساب'!$B$3,U24*$AA24/الافتراضات!$B$26,$AB24='طريقة الحساب'!$B$4,U24*$AA24/الافتراضات!$B$28),"")} -> 0.36731288 | BA24: {=IFERROR(_xlfn.IFS($AB24="عدد الموظفين/الوحدة",V24*$AA24,$AB24='طريقة الحساب'!$B$2,V24*$AA24/الافتراضات!$B$27,$AB24='طريقة الحساب'!$B$3,V24*$AA24/الافتراضات!$B$26,$AB24='طريقة الحساب'!$B$4,V24*$AA24/الافتراضات!$B$28),"")} -> 0.39153131 | BB24: {=IFERROR(_xlfn.IFS($AB24="عدد الموظفين/الوحدة",W24*$AA24,$AB24='طريقة الحساب'!$B$2,W24*$AA24/الافتراضات!$B$27,$AB24='طريقة الحساب'!$B$3,W24*$AA24/الافتراضات!$B$26,$AB24='طريقة الحساب'!$B$4,W24*$AA24/الافتراضات!$B$28),"")} -> 0.41574974 | BC24: {=IFERROR(_xlfn.IFS($AB24="عدد الموظفين/الوحدة",X24*$AA24,$AB24='طريقة الحساب'!$B$2,X24*$AA24/الافتراضات!$B$27,$AB24='طريقة الحساب'!$B$3,X24*$AA24/الافتراضات!$B$26,$AB24='طريقة الحساب'!$B$4,X24*$AA24/الافتراضات!$B$28),"")} -> 0.43996817 | BD24: {=IFERROR(_xlfn.IFS($AB24="عدد الموظفين/الوحدة",Y24*$AA24,$AB24='طريقة الحساب'!$B$2,Y24*$AA24/الافتراضات!$B$27,$AB24='طريقة الحساب'!$B$3,Y24*$AA24/الافتراضات!$B$26,$AB24='طريقة الحساب'!$B$4,Y24*$AA24/الافتراضات!$B$28),"")} -> 0.43996817 | BE24: {=IFERROR(_xlfn.IFS($AB24="عدد الموظفين/الوحدة",Z24*$AA24,$AB24='طريقة الحساب'!$B$2,Z24*$AA24/الافتراضات!$B$27,$AB24='طريقة الحساب'!$B$3,Z24*$AA24/الافتراضات!$B$26,$AB24='طريقة الحساب'!$B$4,Z24*$AA24/الافتراضات!$B$28),"")} -> 0
B25: وزارة البلدية | C25: وكيل الوزارة المساعد لشؤون الخدمات المشتركة | D25: إدارة الموارد البشرية | E25: قسم الرواتب والاجور | F25: معاملات الإسكان الحكومي ( تغيير و تخصيص و تسليم ) و مايترتب عليها من اثار مالية | G25: تكرار | I25: 500 | J25: 500 | K25: 500 | L25: 500 | M25: 500 | N25: 500 | O25: 500 | P25: 1 | Q25: أيام | S25: 500 | T25: 500 | U25: 500 | V25: 500 | W25: 500 | X25: 500 | Y25: 500 | AA25: 1 | AB25: أيام | AO25: =IF(OR(N25="", Y25=""), "", IF(N25<>Y25, "نعم", "لا")) -> لا | AP25: =IF(AO25="نعم", "أضف المبررات هنا", "") | AQ25: =IF(OR(P25="", AA25=""), "", IF(P25<>AA25, "نعم", "لا")) -> لا | AR25: =IF(AQ25="نعم", "[أضف المبررات هنا]", "") | AS25: =IF(OR(Q25="", AB25=""), "", IF(Q25<>AB25, "نعم", "لا")) -> لا | AT25: =IF(AS25="نعم", "[أضف المبررات هنا]", "") | AX25: {=IFERROR(_xlfn.IFS($AB25="عدد الموظفين/الوحدة",S25*$AA25,$AB25='طريقة الحساب'!$B$2,S25*$AA25/الافتراضات!$B$27,$AB25='طريقة الحساب'!$B$3,S25*$AA25/الافتراضات!$B$26,$AB25='طريقة الحساب'!$B$4,S25*$AA25/الافتراضات!$B$28),"")} -> 2.5906736 | AY25: {=IFERROR(_xlfn.IFS($AB25="عدد الموظفين/الوحدة",T25*$AA25,$AB25='طريقة الحساب'!$B$2,T25*$AA25/الافتراضات!$B$27,$AB25='طريقة الحساب'!$B$3,T25*$AA25/الافتراضات!$B$26,$AB25='طريقة الحساب'!$B$4,T25*$AA25/الافتراضات!$B$28),"")} -> 2.5906736 | AZ25: {=IFERROR(_xlfn.IFS($AB25="عدد الموظفين/الوحدة",U25*$AA25,$AB25='طريقة الحساب'!$B$2,U25*$AA25/الافتراضات!$B$27,$AB25='طريقة الحساب'!$B$3,U25*$AA25/الافتراضات!$B$26,$AB25='طريقة الحساب'!$B$4,U25*$AA25/الافتراضات!$B$28),"")} -> 2.5906736 | BA25: {=IFERROR(_xlfn.IFS($AB25="عدد الموظفين/الوحدة",V25*$AA25,$AB25='طريقة الحساب'!$B$2,V25*$AA25/الافتراضات!$B$27,$AB25='طريقة الحساب'!$B$3,V25*$AA25/الافتراضات!$B$26,$AB25='طريقة الحساب'!$B$4,V25*$AA25/الافتراضات!$B$28),"")} -> 2.5906736 | BB25: {=IFERROR(_xlfn.IFS($AB25="عدد الموظفين/الوحدة",W25*$AA25,$AB25='طريقة الحساب'!$B$2,W25*$AA25/الافتراضات!$B$27,$AB25='طريقة الحساب'!$B$3,W25*$AA25/الافتراضات!$B$26,$AB25='طريقة الحساب'!$B$4,W25*$AA25/الافتراضات!$B$28),"")} -> 2.5906736 | BC25: {=IFERROR(_xlfn.IFS($AB25="عدد الموظفين/الوحدة",X25*$AA25,$AB25='طريقة الحساب'!$B$2,X25*$AA25/الافتراضات!$B$27,$AB25='طريقة الحساب'!$B$3,X25*$AA25/الافتراضات!$B$26,$AB25='طريقة الحساب'!$B$4,X25*$AA25/الافتراضات!$B$28),"")} -> 2.5906736 | BD25: {=IFERROR(_xlfn.IFS($AB25="عدد الموظفين/الوحدة",Y25*$AA25,$AB25='طريقة الحساب'!$B$2,Y25*$AA25/الافتراضات!$B$27,$AB25='طريقة الحساب'!$B$3,Y25*$AA25/الافتراضات!$B$26,$AB25='طريقة الحساب'!$B$4,Y25*$AA25/الافتراضات!$B$28),"")} -> 2.5906736 | BE25: {=IFERROR(_xlfn.IFS($AB25="عدد الموظفين/الوحدة",Z25*$AA25,$AB25='طريقة الحساب'!$B$2,Z25*$AA25/الافتراضات!$B$27,$AB25='طريقة الحساب'!$B$3,Z25*$AA25/الافتراضات!$B$26,$AB25='طريقة الحساب'!$B$4,Z25*$AA25/الافتراضات!$B$28),"")} -> 0
B26: وزارة البلدية | C26: وكيل الوزارة المساعد لشؤون الخدمات المشتركة | D26: إدارة الموارد البشرية | E26: قسم الرواتب والاجور | F26: طلبات سندات الصرف | G26: تكرار | I26: 850 | J26: 400 | K26: 420 | L26: 441 | M26: 463.05 | N26: 486.2025 | O26: 486.2025 | P26: 1 | Q26: ساعات | S26: 850 | T26: 400 | U26: 420 | V26: 441 | W26: 463.05 | X26: 486.2025 | Y26: 486.2025 | AA26: 1 | AB26: ساعات | AO26: =IF(OR(N26="", Y26=""), "", IF(N26<>Y26, "نعم", "لا")) -> لا | AP26: =IF(AO26="نعم", "أضف المبررات هنا", "") | AQ26: =IF(OR(P26="", AA26=""), "", IF(P26<>AA26, "نعم", "لا")) -> لا | AR26: =IF(AQ26="نعم", "[أضف المبررات هنا]", "") | AS26: =IF(OR(Q26="", AB26=""), "", IF(Q26<>AB26, "نعم", "لا")) -> لا | AT26: =IF(AS26="نعم", "[أضف المبررات هنا]", "") | AX26: {=IFERROR(_xlfn.IFS($AB26="عدد الموظفين/الوحدة",S26*$AA26,$AB26='طريقة الحساب'!$B$2,S26*$AA26/الافتراضات!$B$27,$AB26='طريقة الحساب'!$B$3,S26*$AA26/الافتراضات!$B$26,$AB26='طريقة الحساب'!$B$4,S26*$AA26/الافتراضات!$B$28),"")} -> 0.85773612 | AY26: {=IFERROR(_xlfn.IFS($AB26="عدد الموظفين/الوحدة",T26*$AA26,$AB26='طريقة الحساب'!$B$2,T26*$AA26/الافتراضات!$B$27,$AB26='طريقة الحساب'!$B$3,T26*$AA26/الافتراضات!$B$26,$AB26='طريقة الحساب'!$B$4,T26*$AA26/الافتراضات!$B$28),"")} -> 0.40364053 | AZ26: {=IFERROR(_xlfn.IFS($AB26="عدد الموظفين/الوحدة",U26*$AA26,$AB26='طريقة الحساب'!$B$2,U26*$AA26/الافتراضات!$B$27,$AB26='طريقة الحساب'!$B$3,U26*$AA26/الافتراضات!$B$26,$AB26='طريقة الحساب'!$B$4,U26*$AA26/الافتراضات!$B$28),"")} -> 0.42382255 | BA26: {=IFERROR(_xlfn.IFS($AB26="عدد الموظفين/الوحدة",V26*$AA26,$AB26='طريقة الحساب'!$B$2,V26*$AA26/الافتراضات!$B$27,$AB26='طريقة الحساب'!$B$3,V26*$AA26/الافتراضات!$B$26,$AB26='طريقة الحساب'!$B$4,V26*$AA26/الافتراضات!$B$28),"")} -> 0.44501368 | BB26: {=IFERROR(_xlfn.IFS($AB26="عدد الموظفين/الوحدة",W26*$AA26,$AB26='طريقة الحساب'!$B$2,W26*$AA26/الافتراضات!$B$27,$AB26='طريقة الحساب'!$B$3,W26*$AA26/الافتراضات!$B$26,$AB26='طريقة الحساب'!$B$4,W26*$AA26/الافتراضات!$B$28),"")} -> 0.46726437 | BC26: {=IFERROR(_xlfn.IFS($AB26="عدد الموظفين/الوحدة",X26*$AA26,$AB26='طريقة الحساب'!$B$2,X26*$AA26/الافتراضات!$B$27,$AB26='طريقة الحساب'!$B$3,X26*$AA26/الافتراضات!$B$26,$AB26='طريقة الحساب'!$B$4,X26*$AA26/الافتراضات!$B$28),"")} -> 0.49062758 | BD26: {=IFERROR(_xlfn.IFS($AB26="عدد الموظفين/الوحدة",Y26*$AA26,$AB26='طريقة الحساب'!$B$2,Y26*$AA26/الافتراضات!$B$27,$AB26='طريقة الحساب'!$B$3,Y26*$AA26/الافتراضات!$B$26,$AB26='طريقة الحساب'!$B$4,Y26*$AA26/الافتراضات!$B$28),"")} -> 0.49062758 | BE26: {=IFERROR(_xlfn.IFS($AB26="عدد الموظفين/الوحدة",Z26*$AA26,$AB26='طريقة الحساب'!$B$2,Z26*$AA26/الافتراضات!$B$27,$AB26='طريقة الحساب'!$B$3,Z26*$AA26/الافتراضات!$B$26,$AB26='طريقة الحساب'!$B$4,Z26*$AA26/الافتراضات!$B$28),"")} -> 0
B27: وزارة البلدية | C27: وكيل الوزارة المساعد لشؤون الخدمات المشتركة | D27: إدارة الموارد البشرية | E27: قسم الرواتب والاجور | F27: العمل الإضافي ( نقدي - تعويضى ) | G27: تكرار | I27: 40213 | J27: 39000 | K27: 40950 | L27: 42997.5 | M27: 45147.375 | N27: 47404.744 | O27: 47404.744 | P27: 5 | Q27: دقائق | S27: 40213 | T27: 39000 | U27: 40950 | V27: 42997.5 | W27: 45147.375 | X27: 47404.744 | Y27: 47404.744 | AA27: 5 | AB27: دقائق | AO27: =IF(OR(N27="", Y27=""), "", IF(N27<>Y27, "نعم", "لا")) -> لا | AP27: =IF(AO27="نعم", "أضف المبررات هنا", "") | AQ27: =IF(OR(P27="", AA27=""), "", IF(P27<>AA27, "نعم", "لا")) -> لا | AR27: =IF(AQ27="نعم", "[أضف المبررات هنا]", "") | AS27: =IF(OR(Q27="", AB27=""), "", IF(Q27<>AB27, "نعم", "لا")) -> لا | AT27: =IF(AS27="نعم", "[أضف المبررات هنا]", "") | AX27: {=IFERROR(_xlfn.IFS($AB27="عدد الموظفين/الوحدة",S27*$AA27,$AB27='طريقة الحساب'!$B$2,S27*$AA27/الافتراضات!$B$27,$AB27='طريقة الحساب'!$B$3,S27*$AA27/الافتراضات!$B$26,$AB27='طريقة الحساب'!$B$4,S27*$AA27/الافتراضات!$B$28),"")} -> 3.3815826 | AY27: {=IFERROR(_xlfn.IFS($AB27="عدد الموظفين/الوحدة",T27*$AA27,$AB27='طريقة الحساب'!$B$2,T27*$AA27/الافتراضات!$B$27,$AB27='طريقة الحساب'!$B$3,T27*$AA27/الافتراضات!$B$26,$AB27='طريقة الحساب'!$B$4,T27*$AA27/الافتراضات!$B$28),"")} -> 3.2795793 | AZ27: {=IFERROR(_xlfn.IFS($AB27="عدد الموظفين/الوحدة",U27*$AA27,$AB27='طريقة الحساب'!$B$2,U27*$AA27/الافتراضات!$B$27,$AB27='طريقة الحساب'!$B$3,U27*$AA27/الافتراضات!$B$26,$AB27='طريقة الحساب'!$B$4,U27*$AA27/الافتراضات!$B$28),"")} -> 3.4435582 | BA27: {=IFERROR(_xlfn.IFS($AB27="عدد الموظفين/الوحدة",V27*$AA27,$AB27='طريقة الحساب'!$B$2,V27*$AA27/الافتراضات!$B$27,$AB27='طريقة الحساب'!$B$3,V27*$AA27/الافتراضات!$B$26,$AB27='طريقة الحساب'!$B$4,V27*$AA27/الافتراضات!$B$28),"")} -> 3.6157362 | BB27: {=IFERROR(_xlfn.IFS($AB27="عدد الموظفين/الوحدة",W27*$AA27,$AB27='طريقة الحساب'!$B$2,W27*$AA27/الافتراضات!$B$27,$AB27='طريقة الحساب'!$B$3,W27*$AA27/الافتراضات!$B$26,$AB27='طريقة الحساب'!$B$4,W27*$AA27/الافتراضات!$B$28),"")} -> 3.796523 | BC27: {=IFERROR(_xlfn.IFS($AB27="عدد الموظفين/الوحدة",X27*$AA27,$AB27='طريقة الحساب'!$B$2,X27*$AA27/الافتراضات!$B$27,$AB27='طريقة الحساب'!$B$3,X27*$AA27/الافتراضات!$B$26,$AB27='طريقة الحساب'!$B$4,X27*$AA27/الافتراضات!$B$28),"")} -> 3.9863491 | BD27: {=IFERROR(_xlfn.IFS($AB27="عدد الموظفين/الوحدة",Y27*$AA27,$AB27='طريقة الحساب'!$B$2,Y27*$AA27/الافتراضات!$B$27,$AB27='طريقة الحساب'!$B$3,Y27*$AA27/الافتراضات!$B$26,$AB27='طريقة الحساب'!$B$4,Y27*$AA27/الافتراضات!$B$28),"")} -> 3.9863491 | BE27: {=IFERROR(_xlfn.IFS($AB27="عدد الموظفين/الوحدة",Z27*$AA27,$AB27='طريقة الحساب'!$B$2,Z27*$AA27/الافتراضات!$B$27,$AB27='طريقة الحساب'!$B$3,Z27*$AA27/الافتراضات!$B$26,$AB27='طريقة الحساب'!$B$4,Z27*$AA27/الافتراضات!$B$28),"")} -> 0
... B48: وزارة البلدية | C48: وكيل الوزارة المساعد لشؤون الخدمات المشتركة | D48: إدارة الموارد البشرية | E48: قسم الرواتب والاجور | F48: اجراء النقل الخارجي | G48: تكرار | I48: 70 | J48: 70 | K48: 75 | L48: 75 | M48: 80 | N48: 85 | O48: 85 | P48: 4 | Q48: ساعات | S48: 70 | T48: 70 | U48: 75 | V48: 75 | W48: 80 | X48: 85 | Y48: 85 | AA48: 4 | AB48: ساعات | AO48: =IF(OR(N48="", Y48=""), "", IF(N48<>Y48, "نعم", "لا")) -> لا | AP48: =IF(AO48="نعم", "أضف المبررات هنا", "") | AQ48: =IF(OR(P48="", AA48=""), "", IF(P48<>AA48, "نعم", "لا")) -> لا | AR48: =IF(AQ48="نعم", "[أضف المبررات هنا]", "") | AS48: =IF(OR(Q48="", AB48=""), "", IF(Q48<>AB48, "نعم", "لا")) -> لا | AT48: =IF(AS48="نعم", "[أضف المبررات هنا]", "") | AX48: {=IFERROR(_xlfn.IFS($AB48="عدد الموظفين/الوحدة",S48*$AA48,$AB48='طريقة الحساب'!$B$2,S48*$AA48/الافتراضات!$B$27,$AB48='طريقة الحساب'!$B$3,S48*$AA48/الافتراضات!$B$26,$AB48='طريقة الحساب'!$B$4,S48*$AA48/الافتراضات!$B$28),"")} -> 0.28254837 | AY48: {=IFERROR(_xlfn.IFS($AB48="عدد الموظفين/الوحدة",T48*$AA48,$AB48='طريقة الحساب'!$B$2,T48*$AA48/الافتراضات!$B$27,$AB48='طريقة الحساب'!$B$3,T48*$AA48/الافتراضات!$B$26,$AB48='طريقة الحساب'!$B$4,T48*$AA48/الافتراضات!$B$28),"")} -> 0.28254837 | AZ48: {=IFERROR(_xlfn.IFS($AB48="عدد الموظفين/الوحدة",U48*$AA48,$AB48='طريقة الحساب'!$B$2,U48*$AA48/الافتراضات!$B$27,$AB48='طريقة الحساب'!$B$3,U48*$AA48/الافتراضات!$B$26,$AB48='طريقة الحساب'!$B$4,U48*$AA48/الافتراضات!$B$28),"")} -> 0.3027304 | BA48: {=IFERROR(_xlfn.IFS($AB48="عدد الموظفين/الوحدة",V48*$AA48,$AB48='طريقة الحساب'!$B$2,V48*$AA48/الافتراضات!$B$27,$AB48='طريقة الحساب'!$B$3,V48*$AA48/الافتراضات!$B$26,$AB48='طريقة الحساب'!$B$4,V48*$AA48/الافتراضات!$B$28),"")} -> 0.3027304 | BB48: {=IFERROR(_xlfn.IFS($AB48="عدد الموظفين/الوحدة",W48*$AA48,$AB48='طريقة الحساب'!$B$2,W48*$AA48/الافتراضات!$B$27,$AB48='طريقة الحساب'!$B$3,W48*$AA48/الافتراضات!$B$26,$AB48='طريقة الحساب'!$B$4,W48*$AA48/الافتراضات!$B$28),"")} -> 0.32291242 | BC48: {=IFERROR(_xlfn.IFS($AB48="عدد الموظفين/الوحدة",X48*$AA48,$AB48='طريقة الحساب'!$B$2,X48*$AA48/الافتراضات!$B$27,$AB48='طريقة الحساب'!$B$3,X48*$AA48/الافتراضات!$B$26,$AB48='طريقة الحساب'!$B$4,X48*$AA48/الافتراضات!$B$28),"")} -> 0.34309445 | BD48: {=IFERROR(_xlfn.IFS($AB48="عدد الموظفين/الوحدة",Y48*$AA48,$AB48='طريقة الحساب'!$B$2,Y48*$AA48/الافتراضات!$B$27,$AB48='طريقة الحساب'!$B$3,Y48*$AA48/الافتراضات!$B$26,$AB48='طريقة الحساب'!$B$4,Y48*$AA48/الافتراضات!$B$28),"")} -> 0.34309445 | BE48: {=IFERROR(_xlfn.IFS($AB48="عدد الموظفين/الوحدة",Z48*$AA48,$AB48='طريقة الحساب'!$B$2,Z48*$AA48/الافتراضات!$B$27,$AB48='طريقة الحساب'!$B$3,Z48*$AA48/الافتراضات!$B$26,$AB48='طريقة الحساب'!$B$4,Z48*$AA48/الافتراضات!$B$28),"")} -> 0
B49: وزارة البلدية | C49: وكيل الوزارة المساعد لشؤون الخدمات المشتركة | D49: إدارة الموارد البشرية | E49: قسم الرواتب والاجور | F49: اجراء الندب الداخلي | G49: تكرار | Q49: ساعات | AB49: ساعات | AO49: =IF(OR(N49="", Y49=""), "", IF(N49<>Y49, "نعم", "لا")) | AP49: =IF(AO49="نعم", "أضف المبررات هنا", "") | AQ49: =IF(OR(P49="", AA49=""), "", IF(P49<>AA49, "نعم", "لا")) | AR49: =IF(AQ49="نعم", "[أضف المبررات هنا]", "") | AS49: =IF(OR(Q49="", AB49=""), "", IF(Q49<>AB49, "نعم", "لا")) -> لا | AT49: =IF(AS49="نعم", "[أضف المبررات هنا]", "") | AX49: {=IFERROR(_xlfn.IFS($AB49="عدد الموظفين/الوحدة",S49*$AA49,$AB49='طريقة الحساب'!$B$2,S49*$AA49/الافتراضات!$B$27,$AB49='طريقة الحساب'!$B$3,S49*$AA49/الافتراضات!$B$26,$AB49='طريقة الحساب'!$B$4,S49*$AA49/الافتراضات!$B$28),"")} -> 0 | AY49: {=IFERROR(_xlfn.IFS($AB49="عدد الموظفين/الوحدة",T49*$AA49,$AB49='طريقة الحساب'!$B$2,T49*$AA49/الافتراضات!$B$27,$AB49='طريقة الحساب'!$B$3,T49*$AA49/الافتراضات!$B$26,$AB49='طريقة الحساب'!$B$4,T49*$AA49/الافتراضات!$B$28),"")} -> 0 | AZ49: {=IFERROR(_xlfn.IFS($AB49="عدد الموظفين/الوحدة",U49*$AA49,$AB49='طريقة الحساب'!$B$2,U49*$AA49/الافتراضات!$B$27,$AB49='طريقة الحساب'!$B$3,U49*$AA49/الافتراضات!$B$26,$AB49='طريقة الحساب'!$B$4,U49*$AA49/الافتراضات!$B$28),"")} -> 0 | BA49: {=IFERROR(_xlfn.IFS($AB49="عدد الموظفين/الوحدة",V49*$AA49,$AB49='طريقة الحساب'!$B$2,V49*$AA49/الافتراضات!$B$27,$AB49='طريقة الحساب'!$B$3,V49*$AA49/الافتراضات!$B$26,$AB49='طريقة الحساب'!$B$4,V49*$AA49/الافتراضات!$B$28),"")} -> 0 | BB49: {=IFERROR(_xlfn.IFS($AB49="عدد الموظفين/الوحدة",W49*$AA49,$AB49='طريقة الحساب'!$B$2,W49*$AA49/الافتراضات!$B$27,$AB49='طريقة الحساب'!$B$3,W49*$AA49/الافتراضات!$B$26,$AB49='طريقة الحساب'!$B$4,W49*$AA49/الافتراضات!$B$28),"")} -> 0 | BC49: {=IFERROR(_xlfn.IFS($AB49="عدد الموظفين/الوحدة",X49*$AA49,$AB49='طريقة الحساب'!$B$2,X49*$AA49/الافتراضات!$B$27,$AB49='طريقة الحساب'!$B$3,X49*$AA49/الافتراضات!$B$26,$AB49='طريقة الحساب'!$B$4,X49*$AA49/الافتراضات!$B$28),"")} -> 0 | BD49: {=IFERROR(_xlfn.IFS($AB49="عدد الموظفين/الوحدة",Y49*$AA49,$AB49='طريقة الحساب'!$B$2,Y49*$AA49/الافتراضات!$B$27,$AB49='طريقة الحساب'!$B$3,Y49*$AA49/الافتراضات!$B$26,$AB49='طريقة الحساب'!$B$4,Y49*$AA49/الافتراضات!$B$28),"")} -> 0 | BE49: {=IFERROR(_xlfn.IFS($AB49="عدد الموظفين/الوحدة",Z49*$AA49,$AB49='طريقة الحساب'!$B$2,Z49*$AA49/الافتراضات!$B$27,$AB49='طريقة الحساب'!$B$3,Z49*$AA49/الافتراضات!$B$26,$AB49='طريقة الحساب'!$B$4,Z49*$AA49/الافتراضات!$B$28),"")} -> 0
B50: وزارة البلدية | C50: وكيل الوزارة المساعد لشؤون الخدمات المشتركة | D50: إدارة الموارد البشرية | E50: قسم الرواتب والاجور | F50: اجراء الندب الخارجي | G50: تكرار | Q50: ساعات | AB50: ساعات | AO50: =IF(OR(N50="", Y50=""), "", IF(N50<>Y50, "نعم", "لا")) | AP50: =IF(AO50="نعم", "أضف المبررات هنا", "") | AQ50: =IF(OR(P50="", AA50=""), "", IF(P50<>AA50, "نعم", "لا")) | AR50: =IF(AQ50="نعم", "[أضف المبررات هنا]", "") | AS50: =IF(OR(Q50="", AB50=""), "", IF(Q50<>AB50, "نعم", "لا")) -> لا | AT50: =IF(AS50="نعم", "[أضف المبررات هنا]", "") | AX50: {=IFERROR(_xlfn.IFS($AB50="عدد الموظفين/الوحدة",S50*$AA50,$AB50='طريقة الحساب'!$B$2,S50*$AA50/الافتراضات!$B$27,$AB50='طريقة الحساب'!$B$3,S50*$AA50/الافتراضات!$B$26,$AB50='طريقة الحساب'!$B$4,S50*$AA50/الافتراضات!$B$28),"")} -> 0 | AY50: {=IFERROR(_xlfn.IFS($AB50="عدد الموظفين/الوحدة",T50*$AA50,$AB50='طريقة الحساب'!$B$2,T50*$AA50/الافتراضات!$B$27,$AB50='طريقة الحساب'!$B$3,T50*$AA50/الافتراضات!$B$26,$AB50='طريقة الحساب'!$B$4,T50*$AA50/الافتراضات!$B$28),"")} -> 0 | AZ50: {=IFERROR(_xlfn.IFS($AB50="عدد الموظفين/الوحدة",U50*$AA50,$AB50='طريقة الحساب'!$B$2,U50*$AA50/الافتراضات!$B$27,$AB50='طريقة الحساب'!$B$3,U50*$AA50/الافتراضات!$B$26,$AB50='طريقة الحساب'!$B$4,U50*$AA50/الافتراضات!$B$28),"")} -> 0 | BA50: {=IFERROR(_xlfn.IFS($AB50="عدد الموظفين/الوحدة",V50*$AA50,$AB50='طريقة الحساب'!$B$2,V50*$AA50/الافتراضات!$B$27,$AB50='طريقة الحساب'!$B$3,V50*$AA50/الافتراضات!$B$26,$AB50='طريقة الحساب'!$B$4,V50*$AA50/الافتراضات!$B$28),"")} -> 0 | BB50: {=IFERROR(_xlfn.IFS($AB50="عدد الموظفين/الوحدة",W50*$AA50,$AB50='طريقة الحساب'!$B$2,W50*$AA50/الافتراضات!$B$27,$AB50='طريقة الحساب'!$B$3,W50*$AA50/الافتراضات!$B$26,$AB50='طريقة الحساب'!$B$4,W50*$AA50/الافتراضات!$B$28),"")} -> 0 | BC50: {=IFERROR(_xlfn.IFS($AB50="عدد الموظفين/الوحدة",X50*$AA50,$AB50='طريقة الحساب'!$B$2,X50*$AA50/الافتراضات!$B$27,$AB50='طريقة الحساب'!$B$3,X50*$AA50/الافتراضات!$B$26,$AB50='طريقة الحساب'!$B$4,X50*$AA50/الافتراضات!$B$28),"")} -> 0 | BD50: {=IFERROR(_xlfn.IFS($AB50="عدد الموظفين/الوحدة",Y50*$AA50,$AB50='طريقة الحساب'!$B$2,Y50*$AA50/الافتراضات!$B$27,$AB50='طريقة الحساب'!$B$3,Y50*$AA50/الافتراضات!$B$26,$AB50='طريقة الحساب'!$B$4,Y50*$AA50/الافتراضات!$B$28),"")} -> 0 | BE50: {=IFERROR(_xlfn.IFS($AB50="عدد الموظفين/الوحدة",Z50*$AA50,$AB50='طريقة الحساب'!$B$2,Z50*$AA50/الافتراضات!$B$27,$AB50='طريقة الحساب'!$B$3,Z50*$AA50/الافتراضات!$B$26,$AB50='طريقة الحساب'!$B$4,Z50*$AA50/الافتراضات!$B$28),"")} -> 0
B51: وزارة البلدية | C51: وكيل الوزارة المساعد لشؤون الخدمات المشتركة | D51: إدارة الموارد البشرية | E51: قسم الرواتب والاجور | F51: اصدار كشوف بالبيانات المطلوبة للادارات | G51: تكرار | I51: 90 | J51: 95 | K51: 95 | L51: 100 | M51: 100 | N51: 100 | O51: 100 | P51: 2 | Q51: ساعات | S51: 90 | T51: 95 | U51: 95 | V51: 100 | W51: 100 | X51: 100 | Y51: 100 | AA51: 2 | AB51: ساعات | AO51: =IF(OR(N51="", Y51=""), "", IF(N51<>Y51, "نعم", "لا")) -> لا | AP51: =IF(AO51="نعم", "أضف المبررات هنا", "") | AQ51: =IF(OR(P51="", AA51=""), "", IF(P51<>AA51, "نعم", "لا")) -> لا | AR51: =IF(AQ51="نعم", "[أضف المبررات هنا]", "") | AS51: =IF(OR(Q51="", AB51=""), "", IF(Q51<>AB51, "نعم", "لا")) -> لا | AT51: =IF(AS51="نعم", "[أضف المبررات هنا]", "") | AX51: {=IFERROR(_xlfn.IFS($AB51="عدد الموظفين/الوحدة",S51*$AA51,$AB51='طريقة الحساب'!$B$2,S51*$AA51/الافتراضات!$B$27,$AB51='طريقة الحساب'!$B$3,S51*$AA51/الافتراضات!$B$26,$AB51='طريقة الحساب'!$B$4,S51*$AA51/الافتراضات!$B$28),"")} -> 0.18163824 | AY51: {=IFERROR(_xlfn.IFS($AB51="عدد الموظفين/الوحدة",T51*$AA51,$AB51='طريقة الحساب'!$B$2,T51*$AA51/الافتراضات!$B$27,$AB51='طريقة الحساب'!$B$3,T51*$AA51/الافتراضات!$B$26,$AB51='طريقة الحساب'!$B$4,T51*$AA51/الافتراضات!$B$28),"")} -> 0.19172925 | AZ51: {=IFERROR(_xlfn.IFS($AB51="عدد الموظفين/الوحدة",U51*$AA51,$AB51='طريقة الحساب'!$B$2,U51*$AA51/الافتراضات!$B$27,$AB51='طريقة الحساب'!$B$3,U51*$AA51/الافتراضات!$B$26,$AB51='طريقة الحساب'!$B$4,U51*$AA51/الافتراضات!$B$28),"")} -> 0.19172925 | BA51: {=IFERROR(_xlfn.IFS($AB51="عدد الموظفين/الوحدة",V51*$AA51,$AB51='طريقة الحساب'!$B$2,V51*$AA51/الافتراضات!$B$27,$AB51='طريقة الحساب'!$B$3,V51*$AA51/الافتراضات!$B$26,$AB51='طريقة الحساب'!$B$4,V51*$AA51/الافتراضات!$B$28),"")} -> 0.20182026 | BB51: {=IFERROR(_xlfn.IFS($AB51="عدد الموظفين/الوحدة",W51*$AA51,$AB51='طريقة الحساب'!$B$2,W51*$AA51/الافتراضات!$B$27,$AB51='طريقة الحساب'!$B$3,W51*$AA51/الافتراضات!$B$26,$AB51='طريقة الحساب'!$B$4,W51*$AA51/الافتراضات!$B$28),"")} -> 0.20182026 | BC51: {=IFERROR(_xlfn.IFS($AB51="عدد الموظفين/الوحدة",X51*$AA51,$AB51='طريقة الحساب'!$B$2,X51*$AA51/الافتراضات!$B$27,$AB51='طريقة الحساب'!$B$3,X51*$AA51/الافتراضات!$B$26,$AB51='طريقة الحساب'!$B$4,X51*$AA51/الافتراضات!$B$28),"")} -> 0.20182026 | BD51: {=IFERROR(_xlfn.IFS($AB51="عدد الموظفين/الوحدة",Y51*$AA51,$AB51='طريقة الحساب'!$B$2,Y51*$AA51/الافتراضات!$B$27,$AB51='طريقة الحساب'!$B$3,Y51*$AA51/الافتراضات!$B$26,$AB51='طريقة الحساب'!$B$4,Y51*$AA51/الافتراضات!$B$28),"")} -> 0.20182026 | BE51: {=IFERROR(_xlfn.IFS($AB51="عدد الموظفين/الوحدة",Z51*$AA51,$AB51='طريقة الحساب'!$B$2,Z51*$AA51/الافتراضات!$B$27,$AB51='طريقة الحساب'!$B$3,Z51*$AA51/الافتراضات!$B$26,$AB51='طريقة الحساب'!$B$4,Z51*$AA51/الافتراضات!$B$28),"")} -> 0
B52: وزارة البلدية | C52: وكيل الوزارة المساعد لشؤون الخدمات المشتركة | D52: إدارة الموارد البشرية | E52: قسم الرواتب والاجور | F52: اجراءات الاستدعاء للخدمة الوطنية | G52: تكرار | I52: 250 | J52: 260 | K52: 260 | L52: 260 | M52: 260 | N52: 260 | O52: 260 | P52: 45 | Q52: دقائق | S52: 250 | T52: 260 | U52: 260 | V52: 260 | W52: 260 | X52: 260 | Y52: 260 | AA52: 45 | AB52: دقائق | AO52: =IF(OR(N52="", Y52=""), "", IF(N52<>Y52, "نعم", "لا")) -> لا | AP52: =IF(AO52="نعم", "أضف المبررات هنا", "") | AQ52: =IF(OR(P52="", AA52=""), "", IF(P52<>AA52, "نعم", "لا")) -> لا | AR52: =IF(AQ52="نعم", "[أضف المبررات هنا]", "") | AS52: =IF(OR(Q52="", AB52=""), "", IF(Q52<>AB52, "نعم", "لا")) -> لا | AT52: =IF(AS52="نعم", "[أضف المبررات هنا]", "") | AX52: {=IFERROR(_xlfn.IFS($AB52="عدد الموظفين/الوحدة",S52*$AA52,$AB52='طريقة الحساب'!$B$2,S52*$AA52/الافتراضات!$B$27,$AB52='طريقة الحساب'!$B$3,S52*$AA52/الافتراضات!$B$26,$AB52='طريقة الحساب'!$B$4,S52*$AA52/الافتراضات!$B$28),"")} -> 0.1892065 | AY52: {=IFERROR(_xlfn.IFS($AB52="عدد الموظفين/الوحدة",T52*$AA52,$AB52='طريقة الحساب'!$B$2,T52*$AA52/الافتراضات!$B$27,$AB52='طريقة الحساب'!$B$3,T52*$AA52/الافتراضات!$B$26,$AB52='طريقة الحساب'!$B$4,T52*$AA52/الافتراضات!$B$28),"")} -> 0.19677476 | AZ52: {=IFERROR(_xlfn.IFS($AB52="عدد الموظفين/الوحدة",U52*$AA52,$AB52='طريقة الحساب'!$B$2,U52*$AA52/الافتراضات!$B$27,$AB52='طريقة الحساب'!$B$3,U52*$AA52/الافتراضات!$B$26,$AB52='طريقة الحساب'!$B$4,U52*$AA52/الافتراضات!$B$28),"")} -> 0.19677476 | BA52: {=IFERROR(_xlfn.IFS($AB52="عدد الموظفين/الوحدة",V52*$AA52,$AB52='طريقة الحساب'!$B$2,V52*$AA52/الافتراضات!$B$27,$AB52='طريقة الحساب'!$B$3,V52*$AA52/الافتراضات!$B$26,$AB52='طريقة الحساب'!$B$4,V52*$AA52/الافتراضات!$B$28),"")} -> 0.19677476 | BB52: {=IFERROR(_xlfn.IFS($AB52="عدد الموظفين/الوحدة",W52*$AA52,$AB52='طريقة الحساب'!$B$2,W52*$AA52/الافتراضات!$B$27,$AB52='طريقة الحساب'!$B$3,W52*$AA52/الافتراضات!$B$26,$AB52='طريقة الحساب'!$B$4,W52*$AA52/الافتراضات!$B$28),"")} -> 0.19677476 | BC52: {=IFERROR(_xlfn.IFS($AB52="عدد الموظفين/الوحدة",X52*$AA52,$AB52='طريقة الحساب'!$B$2,X52*$AA52/الافتراضات!$B$27,$AB52='طريقة الحساب'!$B$3,X52*$AA52/الافتراضات!$B$26,$AB52='طريقة الحساب'!$B$4,X52*$AA52/الافتراضات!$B$28),"")} -> 0.19677476 | BD52: {=IFERROR(_xlfn.IFS($AB52="عدد الموظفين/الوحدة",Y52*$AA52,$AB52='طريقة الحساب'!$B$2,Y52*$AA52/الافتراضات!$B$27,$AB52='طريقة الحساب'!$B$3,Y52*$AA52/الافتراضات!$B$26,$AB52='طريقة الحساب'!$B$4,Y52*$AA52/الافتراضات!$B$28),"")} -> 0.19677476 | BE52: {=IFERROR(_xlfn.IFS($AB52="عدد الموظفين/الوحدة",Z52*$AA52,$AB52='طريقة الحساب'!$B$2,Z52*$AA52/الافتراضات!$B$27,$AB52='طريقة الحساب'!$B$3,Z52*$AA52/الافتراضات!$B$26,$AB52='طريقة الحساب'!$B$4,Z52*$AA52/الافتراضات!$B$28),"")} -> 0
B53: وزارة البلدية | C53: وكيل الوزارة المساعد لشؤون الخدمات المشتركة | D53: إدارة الموارد البشرية | E53: قسم الرواتب والاجور | F53: اجراء اصدار كشوفات ببوغ سن الستين | G53: تكرار | I53: 12 | J53: 12 | K53: 12 | L53: 12 | M53: 12 | N53: 12 | O53: 12 | P53: 30 | Q53: دقائق | S53: 12 | T53: 12 | U53: 12 | V53: 12 | W53: 12 | X53: 12 | Y53: 12 | AA53: 30 | AB53: دقائق | AO53: =IF(OR(N53="", Y53=""), "", IF(N53<>Y53, "نعم", "لا")) -> لا | AP53: =IF(AO53="نعم", "أضف المبررات هنا", "") | AQ53: =IF(OR(P53="", AA53=""), "", IF(P53<>AA53, "نعم", "لا")) -> لا | AR53: =IF(AQ53="نعم", "[أضف المبررات هنا]", "") | AS53: =IF(OR(Q53="", AB53=""), "", IF(Q53<>AB53, "نعم", "لا")) -> لا | AT53: =IF(AS53="نعم", "[أضف المبررات هنا]", "") | AX53: {=IFERROR(_xlfn.IFS($AB53="عدد الموظفين/الوحدة",S53*$AA53,$AB53='طريقة الحساب'!$B$2,S53*$AA53/الافتراضات!$B$27,$AB53='طريقة الحساب'!$B$3,S53*$AA53/الافتراضات!$B$26,$AB53='طريقة الحساب'!$B$4,S53*$AA53/الافتراضات!$B$28),"")} -> 0.0060546079 | AY53: {=IFERROR(_xlfn.IFS($AB53="عدد الموظفين/الوحدة",T53*$AA53,$AB53='طريقة الحساب'!$B$2,T53*$AA53/الافتراضات!$B$27,$AB53='طريقة الحساب'!$B$3,T53*$AA53/الافتراضات!$B$26,$AB53='طريقة الحساب'!$B$4,T53*$AA53/الافتراضات!$B$28),"")} -> 0.0060546079 | AZ53: {=IFERROR(_xlfn.IFS($AB53="عدد الموظفين/الوحدة",U53*$AA53,$AB53='طريقة الحساب'!$B$2,U53*$AA53/الافتراضات!$B$27,$AB53='طريقة الحساب'!$B$3,U53*$AA53/الافتراضات!$B$26,$AB53='طريقة الحساب'!$B$4,U53*$AA53/الافتراضات!$B$28),"")} -> 0.0060546079 | BA53: {=IFERROR(_xlfn.IFS($AB53="عدد الموظفين/الوحدة",V53*$AA53,$AB53='طريقة الحساب'!$B$2,V53*$AA53/الافتراضات!$B$27,$AB53='طريقة الحساب'!$B$3,V53*$AA53/الافتراضات!$B$26,$AB53='طريقة الحساب'!$B$4,V53*$AA53/الافتراضات!$B$28),"")} -> 0.0060546079 | BB53: {=IFERROR(_xlfn.IFS($AB53="عدد الموظفين/الوحدة",W53*$AA53,$AB53='طريقة الحساب'!$B$2,W53*$AA53/الافتراضات!$B$27,$AB53='طريقة الحساب'!$B$3,W53*$AA53/الافتراضات!$B$26,$AB53='طريقة الحساب'!$B$4,W53*$AA53/الافتراضات!$B$28),"")} -> 0.0060546079 | BC53: {=IFERROR(_xlfn.IFS($AB53="عدد الموظفين/الوحدة",X53*$AA53,$AB53='طريقة الحساب'!$B$2,X53*$AA53/الافتراضات!$B$27,$AB53='طريقة الحساب'!$B$3,X53*$AA53/الافتراضات!$B$26,$AB53='طريقة الحساب'!$B$4,X53*$AA53/الافتراضات!$B$28),"")} -> 0.0060546079 | BD53: {=IFERROR(_xlfn.IFS($AB53="عدد الموظفين/الوحدة",Y53*$AA53,$AB53='طريقة الحساب'!$B$2,Y53*$AA53/الافتراضات!$B$27,$AB53='طريقة الحساب'!$B$3,Y53*$AA53/الافتراضات!$B$26,$AB53='طريقة الحساب'!$B$4,Y53*$AA53/الافتراضات!$B$28),"")} -> 0.0060546079 | BE53: {=IFERROR(_xlfn.IFS($AB53="عدد الموظفين/الوحدة",Z53*$AA53,$AB53='طريقة الحساب'!$B$2,Z53*$AA53/الافتراضات!$B$27,$AB53='طريقة الحساب'!$B$3,Z53*$AA53/الافتراضات!$B$26,$AB53='طريقة الحساب'!$B$4,Z53*$AA53/الافتراضات!$B$28),"")} -> 0
